2024-09-10 12:25:23,588 [ERROR]: core_parameter.py(_run_diag:269) >> Error in e3sm_diags.driver.annual_cycle_zonal_mean_driver
2024-09-10 12:25:23,667 [ERROR]: core_parameter.py(_run_diag:269) >> Error in e3sm_diags.driver.annual_cycle_zonal_mean_driver
2024-09-10 12:25:23,743 [ERROR]: core_parameter.py(_run_diag:269) >> Error in e3sm_diags.driver.annual_cycle_zonal_mean_driver
2024-09-10 12:25:23,793 [ERROR]: core_parameter.py(_run_diag:269) >> Error in e3sm_diags.driver.lat_lon_driver
2024-09-10 12:25:23,795 [ERROR]: core_parameter.py(_run_diag:269) >> Error in e3sm_diags.driver.lat_lon_driver
2024-09-10 12:25:23,795 [ERROR]: core_parameter.py(_run_diag:269) >> Error in e3sm_diags.driver.polar_driver
2024-09-10 12:25:23,798 [ERROR]: core_parameter.py(_run_diag:269) >> Error in e3sm_diags.driver.lat_lon_driver
2024-09-10 12:25:23,818 [ERROR]: core_parameter.py(_run_diag:269) >> Error in e3sm_diags.driver.lat_lon_driver
2024-09-10 12:25:23,822 [ERROR]: core_parameter.py(_run_diag:269) >> Error in e3sm_diags.driver.annual_cycle_zonal_mean_driver
2024-09-10 12:25:23,847 [ERROR]: core_parameter.py(_run_diag:269) >> Error in e3sm_diags.driver.polar_driver
2024-09-10 12:25:23,958 [ERROR]: core_parameter.py(_run_diag:269) >> Error in e3sm_diags.driver.polar_driver
2024-09-10 12:25:24,057 [ERROR]: core_parameter.py(_run_diag:269) >> Error in e3sm_diags.driver.annual_cycle_zonal_mean_driver
2024-09-10 12:25:24,136 [ERROR]: core_parameter.py(_run_diag:269) >> Error in e3sm_diags.driver.lat_lon_driver
2024-09-10 12:25:24,155 [ERROR]: core_parameter.py(_run_diag:269) >> Error in e3sm_diags.driver.annual_cycle_zonal_mean_driver
2024-09-10 12:25:24,160 [ERROR]: core_parameter.py(_run_diag:269) >> Error in e3sm_diags.driver.lat_lon_driver
2024-09-10 12:25:24,169 [ERROR]: core_parameter.py(_run_diag:269) >> Error in e3sm_diags.driver.polar_driver
2024-09-10 12:25:24,230 [ERROR]: core_parameter.py(_run_diag:269) >> Error in e3sm_diags.driver.lat_lon_driver
2024-09-10 12:25:24,238 [ERROR]: core_parameter.py(_run_diag:269) >> Error in e3sm_diags.driver.lat_lon_driver
2024-09-10 12:25:24,238 [ERROR]: core_parameter.py(_run_diag:269) >> Error in e3sm_diags.driver.polar_driver
2024-09-10 12:25:24,270 [ERROR]: core_parameter.py(_run_diag:269) >> Error in e3sm_diags.driver.polar_driver
2024-09-10 12:25:24,288 [ERROR]: core_parameter.py(_run_diag:269) >> Error in e3sm_diags.driver.annual_cycle_zonal_mean_driver
2024-09-10 12:25:24,350 [ERROR]: core_parameter.py(_run_diag:269) >> Error in e3sm_diags.driver.lat_lon_driver
2024-09-10 12:25:24,370 [ERROR]: core_parameter.py(_run_diag:269) >> Error in e3sm_diags.driver.annual_cycle_zonal_mean_driver
2024-09-10 12:25:24,376 [ERROR]: core_parameter.py(_run_diag:269) >> Error in e3sm_diags.driver.lat_lon_driver
2024-09-10 12:25:24,531 [ERROR]: core_parameter.py(_run_diag:269) >> Error in e3sm_diags.driver.polar_driver
2024-09-10 12:25:24,532 [ERROR]: core_parameter.py(_run_diag:269) >> Error in e3sm_diags.driver.polar_driver
2024-09-10 12:25:24,535 [ERROR]: core_parameter.py(_run_diag:269) >> Error in e3sm_diags.driver.polar_driver
2024-09-10 12:25:24,543 [ERROR]: core_parameter.py(_run_diag:269) >> Error in e3sm_diags.driver.lat_lon_driver
2024-09-10 12:25:24,550 [ERROR]: core_parameter.py(_run_diag:269) >> Error in e3sm_diags.driver.lat_lon_driver
2024-09-10 12:25:24,628 [ERROR]: core_parameter.py(_run_diag:269) >> Error in e3sm_diags.driver.lat_lon_driver
2024-09-10 12:25:24,638 [ERROR]: core_parameter.py(_run_diag:269) >> Error in e3sm_diags.driver.lat_lon_driver
2024-09-10 12:25:24,698 [ERROR]: core_parameter.py(_run_diag:269) >> Error in e3sm_diags.driver.polar_driver
2024-09-10 12:25:24,704 [ERROR]: core_parameter.py(_run_diag:269) >> Error in e3sm_diags.driver.polar_driver
2024-09-10 12:25:24,705 [ERROR]: core_parameter.py(_run_diag:269) >> Error in e3sm_diags.driver.polar_driver
2024-09-10 12:25:24,708 [ERROR]: core_parameter.py(_run_diag:269) >> Error in e3sm_diags.driver.lat_lon_driver
2024-09-10 12:25:24,754 [ERROR]: core_parameter.py(_run_diag:269) >> Error in e3sm_diags.driver.lat_lon_driver
2024-09-10 12:25:24,853 [ERROR]: core_parameter.py(_run_diag:269) >> Error in e3sm_diags.driver.lat_lon_driver
2024-09-10 12:25:24,910 [ERROR]: core_parameter.py(_run_diag:269) >> Error in e3sm_diags.driver.polar_driver
2024-09-10 12:25:24,948 [ERROR]: core_parameter.py(_run_diag:269) >> Error in e3sm_diags.driver.polar_driver
2024-09-10 12:25:24,967 [ERROR]: core_parameter.py(_run_diag:269) >> Error in e3sm_diags.driver.polar_driver
2024-09-10 12:25:25,133 [ERROR]: core_parameter.py(_run_diag:269) >> Error in e3sm_diags.driver.lat_lon_driver
2024-09-10 12:25:25,165 [ERROR]: core_parameter.py(_run_diag:269) >> Error in e3sm_diags.driver.lat_lon_driver
2024-09-10 12:25:25,187 [ERROR]: core_parameter.py(_run_diag:269) >> Error in e3sm_diags.driver.polar_driver
2024-09-10 12:25:25,232 [ERROR]: core_parameter.py(_run_diag:269) >> Error in e3sm_diags.driver.polar_driver
2024-09-10 12:25:25,239 [ERROR]: core_parameter.py(_run_diag:269) >> Error in e3sm_diags.driver.polar_driver
2024-09-10 12:25:25,297 [ERROR]: core_parameter.py(_run_diag:269) >> Error in e3sm_diags.driver.lat_lon_driver
2024-09-10 12:25:25,331 [ERROR]: core_parameter.py(_run_diag:269) >> Error in e3sm_diags.driver.lat_lon_driver
2024-09-10 12:25:25,338 [ERROR]: core_parameter.py(_run_diag:269) >> Error in e3sm_diags.driver.polar_driver
2024-09-10 12:25:25,395 [ERROR]: core_parameter.py(_run_diag:269) >> Error in e3sm_diags.driver.polar_driver
2024-09-10 12:25:25,402 [ERROR]: core_parameter.py(_run_diag:269) >> Error in e3sm_diags.driver.polar_driver
2024-09-10 12:25:25,461 [ERROR]: core_parameter.py(_run_diag:269) >> Error in e3sm_diags.driver.lat_lon_driver
2024-09-10 12:25:25,462 [ERROR]: core_parameter.py(_run_diag:269) >> Error in e3sm_diags.driver.lat_lon_driver
2024-09-10 12:25:25,488 [ERROR]: core_parameter.py(_run_diag:269) >> Error in e3sm_diags.driver.polar_driver
2024-09-10 12:25:25,505 [ERROR]: core_parameter.py(_run_diag:269) >> Error in e3sm_diags.driver.lat_lon_driver
2024-09-10 12:25:25,559 [ERROR]: core_parameter.py(_run_diag:269) >> Error in e3sm_diags.driver.polar_driver
2024-09-10 12:25:25,564 [ERROR]: core_parameter.py(_run_diag:269) >> Error in e3sm_diags.driver.polar_driver
2024-09-10 12:25:25,620 [ERROR]: core_parameter.py(_run_diag:269) >> Error in e3sm_diags.driver.lat_lon_driver
2024-09-10 12:25:25,639 [ERROR]: core_parameter.py(_run_diag:269) >> Error in e3sm_diags.driver.polar_driver
2024-09-10 12:25:25,660 [ERROR]: core_parameter.py(_run_diag:269) >> Error in e3sm_diags.driver.lat_lon_driver
2024-09-10 12:25:25,719 [ERROR]: core_parameter.py(_run_diag:269) >> Error in e3sm_diags.driver.polar_driver
2024-09-10 12:25:25,740 [ERROR]: core_parameter.py(_run_diag:269) >> Error in e3sm_diags.driver.polar_driver
2024-09-10 12:25:25,777 [ERROR]: core_parameter.py(_run_diag:269) >> Error in e3sm_diags.driver.lat_lon_driver
2024-09-10 12:25:25,789 [ERROR]: core_parameter.py(_run_diag:269) >> Error in e3sm_diags.driver.polar_driver
2024-09-10 12:25:25,813 [ERROR]: core_parameter.py(_run_diag:269) >> Error in e3sm_diags.driver.lat_lon_driver
2024-09-10 12:25:25,873 [ERROR]: core_parameter.py(_run_diag:269) >> Error in e3sm_diags.driver.polar_driver
2024-09-10 12:25:25,900 [ERROR]: core_parameter.py(_run_diag:269) >> Error in e3sm_diags.driver.polar_driver
2024-09-10 12:25:25,929 [ERROR]: core_parameter.py(_run_diag:269) >> Error in e3sm_diags.driver.lat_lon_driver
2024-09-10 12:25:25,937 [ERROR]: core_parameter.py(_run_diag:269) >> Error in e3sm_diags.driver.polar_driver
2024-09-10 12:25:25,968 [ERROR]: core_parameter.py(_run_diag:269) >> Error in e3sm_diags.driver.lat_lon_driver
2024-09-10 12:25:26,032 [ERROR]: core_parameter.py(_run_diag:269) >> Error in e3sm_diags.driver.polar_driver
2024-09-10 12:25:26,064 [ERROR]: core_parameter.py(_run_diag:269) >> Error in e3sm_diags.driver.polar_driver
2024-09-10 12:25:26,083 [ERROR]: core_parameter.py(_run_diag:269) >> Error in e3sm_diags.driver.lat_lon_driver
2024-09-10 12:25:26,090 [ERROR]: core_parameter.py(_run_diag:269) >> Error in e3sm_diags.driver.polar_driver
2024-09-10 12:25:26,128 [ERROR]: core_parameter.py(_run_diag:269) >> Error in e3sm_diags.driver.lat_lon_driver
2024-09-10 12:25:26,189 [ERROR]: core_parameter.py(_run_diag:269) >> Error in e3sm_diags.driver.polar_driver
2024-09-10 12:25:26,227 [ERROR]: core_parameter.py(_run_diag:269) >> Error in e3sm_diags.driver.polar_driver
2024-09-10 12:25:26,236 [ERROR]: core_parameter.py(_run_diag:269) >> Error in e3sm_diags.driver.lat_lon_driver
2024-09-10 12:25:26,248 [ERROR]: core_parameter.py(_run_diag:269) >> Error in e3sm_diags.driver.polar_driver
2024-09-10 12:25:26,283 [ERROR]: core_parameter.py(_run_diag:269) >> Error in e3sm_diags.driver.lat_lon_driver
2024-09-10 12:25:26,373 [ERROR]: core_parameter.py(_run_diag:269) >> Error in e3sm_diags.driver.polar_driver
2024-09-10 12:25:26,408 [ERROR]: core_parameter.py(_run_diag:269) >> Error in e3sm_diags.driver.polar_driver
2024-09-10 12:25:26,425 [ERROR]: core_parameter.py(_run_diag:269) >> Error in e3sm_diags.driver.lat_lon_driver
2024-09-10 12:25:26,473 [ERROR]: core_parameter.py(_run_diag:269) >> Error in e3sm_diags.driver.lat_lon_driver
2024-09-10 12:25:26,548 [ERROR]: core_parameter.py(_run_diag:269) >> Error in e3sm_diags.driver.polar_driver
2024-09-10 12:25:26,567 [ERROR]: core_parameter.py(_run_diag:269) >> Error in e3sm_diags.driver.polar_driver
2024-09-10 12:25:26,594 [ERROR]: core_parameter.py(_run_diag:269) >> Error in e3sm_diags.driver.lat_lon_driver
2024-09-10 12:25:26,627 [ERROR]: core_parameter.py(_run_diag:269) >> Error in e3sm_diags.driver.lat_lon_driver
2024-09-10 12:25:26,709 [ERROR]: core_parameter.py(_run_diag:269) >> Error in e3sm_diags.driver.polar_driver
2024-09-10 12:25:26,725 [ERROR]: core_parameter.py(_run_diag:269) >> Error in e3sm_diags.driver.polar_driver
2024-09-10 12:25:26,756 [ERROR]: core_parameter.py(_run_diag:269) >> Error in e3sm_diags.driver.lat_lon_driver
2024-09-10 12:25:26,784 [ERROR]: core_parameter.py(_run_diag:269) >> Error in e3sm_diags.driver.lat_lon_driver
2024-09-10 12:25:26,866 [ERROR]: core_parameter.py(_run_diag:269) >> Error in e3sm_diags.driver.polar_driver
2024-09-10 12:25:26,915 [ERROR]: core_parameter.py(_run_diag:269) >> Error in e3sm_diags.driver.lat_lon_driver
2024-09-10 12:25:27,037 [ERROR]: core_parameter.py(_run_diag:269) >> Error in e3sm_diags.driver.polar_driver
2024-09-10 12:25:27,137 [ERROR]: core_parameter.py(_run_diag:269) >> Error in e3sm_diags.driver.lat_lon_driver
2024-09-10 12:25:27,300 [ERROR]: core_parameter.py(_run_diag:269) >> Error in e3sm_diags.driver.lat_lon_driver
2024-09-10 12:25:27,300 [ERROR]: core_parameter.py(_run_diag:269) >> Error in e3sm_diags.driver.polar_driver
2024-09-10 12:25:27,539 [ERROR]: core_parameter.py(_run_diag:269) >> Error in e3sm_diags.driver.lat_lon_driver
2024-09-10 12:25:27,540 [ERROR]: core_parameter.py(_run_diag:269) >> Error in e3sm_diags.driver.polar_driver
2024-09-10 12:25:27,804 [ERROR]: core_parameter.py(_run_diag:269) >> Error in e3sm_diags.driver.polar_driver
2024-09-10 12:25:27,831 [ERROR]: core_parameter.py(_run_diag:269) >> Error in e3sm_diags.driver.lat_lon_driver
2024-09-10 12:25:28,015 [ERROR]: core_parameter.py(_run_diag:269) >> Error in e3sm_diags.driver.polar_driver
2024-09-10 12:25:28,127 [ERROR]: core_parameter.py(_run_diag:269) >> Error in e3sm_diags.driver.lat_lon_driver
2024-09-10 12:25:28,250 [ERROR]: core_parameter.py(_run_diag:269) >> Error in e3sm_diags.driver.polar_driver
2024-09-10 12:25:28,395 [ERROR]: core_parameter.py(_run_diag:269) >> Error in e3sm_diags.driver.polar_driver
2024-09-10 12:25:28,423 [ERROR]: core_parameter.py(_run_diag:269) >> Error in e3sm_diags.driver.lat_lon_driver
2024-09-10 12:25:28,541 [ERROR]: core_parameter.py(_run_diag:269) >> Error in e3sm_diags.driver.polar_driver
2024-09-10 12:25:28,605 [ERROR]: core_parameter.py(_run_diag:269) >> Error in e3sm_diags.driver.lat_lon_driver
2024-09-10 12:25:28,695 [ERROR]: core_parameter.py(_run_diag:269) >> Error in e3sm_diags.driver.polar_driver
2024-09-10 12:25:28,757 [ERROR]: core_parameter.py(_run_diag:269) >> Error in e3sm_diags.driver.lat_lon_driver
2024-09-10 12:25:28,843 [ERROR]: core_parameter.py(_run_diag:269) >> Error in e3sm_diags.driver.polar_driver
2024-09-10 12:25:28,910 [ERROR]: core_parameter.py(_run_diag:269) >> Error in e3sm_diags.driver.polar_driver
2024-09-10 12:25:28,989 [ERROR]: core_parameter.py(_run_diag:269) >> Error in e3sm_diags.driver.polar_driver
2024-09-10 12:25:29,061 [ERROR]: core_parameter.py(_run_diag:269) >> Error in e3sm_diags.driver.polar_driver
2024-09-10 12:25:29,134 [ERROR]: core_parameter.py(_run_diag:269) >> Error in e3sm_diags.driver.polar_driver
2024-09-10 12:25:29,401 [ERROR]: core_parameter.py(_run_diag:269) >> Error in e3sm_diags.driver.polar_driver
2024-09-10 12:25:29,402 [ERROR]: core_parameter.py(_run_diag:269) >> Error in e3sm_diags.driver.polar_driver
2024-09-10 12:25:29,675 [ERROR]: core_parameter.py(_run_diag:269) >> Error in e3sm_diags.driver.polar_driver
2024-09-10 12:25:29,744 [ERROR]: core_parameter.py(_run_diag:269) >> Error in e3sm_diags.driver.polar_driver
2024-09-10 12:25:29,827 [ERROR]: core_parameter.py(_run_diag:269) >> Error in e3sm_diags.driver.polar_driver
2024-09-10 12:25:29,892 [ERROR]: core_parameter.py(_run_diag:269) >> Error in e3sm_diags.driver.polar_driver
2024-09-10 12:25:29,979 [ERROR]: core_parameter.py(_run_diag:269) >> Error in e3sm_diags.driver.polar_driver
2024-09-10 12:25:30,037 [ERROR]: core_parameter.py(_run_diag:269) >> Error in e3sm_diags.driver.polar_driver
2024-09-10 12:25:30,126 [ERROR]: core_parameter.py(_run_diag:269) >> Error in e3sm_diags.driver.annual_cycle_zonal_mean_driver
2024-09-10 12:25:30,133 [ERROR]: core_parameter.py(_run_diag:269) >> Error in e3sm_diags.driver.polar_driver
2024-09-10 12:25:30,186 [ERROR]: core_parameter.py(_run_diag:269) >> Error in e3sm_diags.driver.polar_driver
2024-09-10 12:25:30,199 [ERROR]: core_parameter.py(_run_diag:269) >> Error in e3sm_diags.driver.annual_cycle_zonal_mean_driver
2024-09-10 12:25:30,362 [ERROR]: core_parameter.py(_run_diag:269) >> Error in e3sm_diags.driver.annual_cycle_zonal_mean_driver
2024-09-10 12:25:30,390 [ERROR]: core_parameter.py(_run_diag:269) >> Error in e3sm_diags.driver.polar_driver
2024-09-10 12:25:30,422 [ERROR]: core_parameter.py(_run_diag:269) >> Error in e3sm_diags.driver.polar_driver
2024-09-10 12:25:30,540 [ERROR]: core_parameter.py(_run_diag:269) >> Error in e3sm_diags.driver.polar_driver
2024-09-10 12:25:30,570 [ERROR]: core_parameter.py(_run_diag:269) >> Error in e3sm_diags.driver.polar_driver
2024-09-10 12:25:30,694 [ERROR]: core_parameter.py(_run_diag:269) >> Error in e3sm_diags.driver.polar_driver
2024-09-10 12:25:30,716 [ERROR]: core_parameter.py(_run_diag:269) >> Error in e3sm_diags.driver.polar_driver
2024-09-10 12:25:30,843 [ERROR]: core_parameter.py(_run_diag:269) >> Error in e3sm_diags.driver.polar_driver
2024-09-10 12:25:30,862 [ERROR]: core_parameter.py(_run_diag:269) >> Error in e3sm_diags.driver.polar_driver
2024-09-10 12:25:30,992 [ERROR]: core_parameter.py(_run_diag:269) >> Error in e3sm_diags.driver.polar_driver
2024-09-10 12:25:31,010 [ERROR]: core_parameter.py(_run_diag:269) >> Error in e3sm_diags.driver.polar_driver
2024-09-10 12:25:31,233 [ERROR]: core_parameter.py(_run_diag:269) >> Error in e3sm_diags.driver.polar_driver
2024-09-10 12:25:31,387 [ERROR]: core_parameter.py(_run_diag:269) >> Error in e3sm_diags.driver.polar_driver
2024-09-10 12:25:31,536 [ERROR]: core_parameter.py(_run_diag:269) >> Error in e3sm_diags.driver.polar_driver
2024-09-10 12:25:31,683 [ERROR]: core_parameter.py(_run_diag:269) >> Error in e3sm_diags.driver.polar_driver
2024-09-10 12:25:31,828 [ERROR]: core_parameter.py(_run_diag:269) >> Error in e3sm_diags.driver.polar_driver
2024-09-10 12:25:31,974 [ERROR]: core_parameter.py(_run_diag:269) >> Error in e3sm_diags.driver.polar_driver
2024-09-10 12:25:32,121 [ERROR]: core_parameter.py(_run_diag:269) >> Error in e3sm_diags.driver.polar_driver
2024-09-10 12:25:32,269 [ERROR]: core_parameter.py(_run_diag:269) >> Error in e3sm_diags.driver.polar_driver
2024-09-10 12:25:32,420 [ERROR]: core_parameter.py(_run_diag:269) >> Error in e3sm_diags.driver.polar_driver
2024-09-10 12:25:32,795 [ERROR]: core_parameter.py(_run_diag:269) >> Error in e3sm_diags.driver.polar_driver
2024-09-10 12:25:33,028 [ERROR]: core_parameter.py(_run_diag:269) >> Error in e3sm_diags.driver.polar_driver
2024-09-10 12:25:33,190 [ERROR]: core_parameter.py(_run_diag:269) >> Error in e3sm_diags.driver.polar_driver
2024-09-10 12:25:33,350 [ERROR]: core_parameter.py(_run_diag:269) >> Error in e3sm_diags.driver.polar_driver
2024-09-10 12:25:33,506 [ERROR]: core_parameter.py(_run_diag:269) >> Error in e3sm_diags.driver.zonal_mean_xy_driver
2024-09-10 12:25:33,509 [ERROR]: core_parameter.py(_run_diag:269) >> Error in e3sm_diags.driver.polar_driver
2024-09-10 12:25:33,584 [ERROR]: core_parameter.py(_run_diag:269) >> Error in e3sm_diags.driver.zonal_mean_xy_driver
2024-09-10 12:25:33,667 [ERROR]: core_parameter.py(_run_diag:269) >> Error in e3sm_diags.driver.polar_driver
2024-09-10 12:25:33,731 [ERROR]: core_parameter.py(_run_diag:269) >> Error in e3sm_diags.driver.lat_lon_driver
2024-09-10 12:25:33,820 [ERROR]: core_parameter.py(_run_diag:269) >> Error in e3sm_diags.driver.polar_driver
2024-09-10 12:25:33,879 [ERROR]: core_parameter.py(_run_diag:269) >> Error in e3sm_diags.driver.lat_lon_driver
2024-09-10 12:25:33,969 [ERROR]: core_parameter.py(_run_diag:269) >> Error in e3sm_diags.driver.polar_driver
2024-09-10 12:25:34,118 [ERROR]: core_parameter.py(_run_diag:269) >> Error in e3sm_diags.driver.polar_driver
2024-09-10 12:25:34,347 [ERROR]: core_parameter.py(_run_diag:269) >> Error in e3sm_diags.driver.polar_driver
2024-09-10 12:25:34,498 [ERROR]: core_parameter.py(_run_diag:269) >> Error in e3sm_diags.driver.polar_driver
2024-09-10 12:25:34,649 [ERROR]: core_parameter.py(_run_diag:269) >> Error in e3sm_diags.driver.polar_driver
2024-09-10 12:25:34,696 [ERROR]: area_mean_time_series_driver.py(run_diag:139) >> No valid value for reference datasets available for the specified time range
2024-09-10 12:25:34,711 [ERROR]: area_mean_time_series_driver.py(run_diag:139) >> No valid value for reference datasets available for the specified time range
2024-09-10 12:25:34,798 [ERROR]: core_parameter.py(_run_diag:269) >> Error in e3sm_diags.driver.polar_driver
2024-09-10 12:25:37,561 [ERROR]: area_mean_time_series_driver.py(run_diag:139) >> No valid value for reference datasets available for the specified time range
2024-09-10 12:25:37,563 [ERROR]: area_mean_time_series_driver.py(run_diag:139) >> No valid value for reference datasets available for the specified time range
2024-09-10 12:25:40,365 [ERROR]: area_mean_time_series_driver.py(run_diag:139) >> No valid value for reference datasets available for the specified time range
2024-09-10 12:25:40,367 [ERROR]: area_mean_time_series_driver.py(run_diag:139) >> No valid value for reference datasets available for the specified time range
2024-09-10 12:25:40,514 [ERROR]: area_mean_time_series_driver.py(run_diag:139) >> No valid value for reference datasets available for the specified time range
2024-09-10 12:25:40,515 [ERROR]: area_mean_time_series_driver.py(run_diag:139) >> No valid value for reference datasets available for the specified time range
2024-09-10 12:25:40,648 [ERROR]: area_mean_time_series_driver.py(run_diag:139) >> No valid value for reference datasets available for the specified time range
2024-09-10 12:25:40,649 [ERROR]: area_mean_time_series_driver.py(run_diag:139) >> No valid value for reference datasets available for the specified time range
2024-09-10 12:25:40,837 [ERROR]: area_mean_time_series_driver.py(run_diag:139) >> No valid value for reference datasets available for the specified time range
2024-09-10 12:25:40,838 [ERROR]: area_mean_time_series_driver.py(run_diag:139) >> No valid value for reference datasets available for the specified time range
2024-09-10 12:25:40,970 [ERROR]: area_mean_time_series_driver.py(run_diag:139) >> No valid value for reference datasets available for the specified time range
2024-09-10 12:25:40,971 [ERROR]: area_mean_time_series_driver.py(run_diag:139) >> No valid value for reference datasets available for the specified time range
2024-09-10 12:25:41,159 [ERROR]: area_mean_time_series_driver.py(run_diag:139) >> No valid value for reference datasets available for the specified time range
2024-09-10 12:25:41,161 [ERROR]: area_mean_time_series_driver.py(run_diag:139) >> No valid value for reference datasets available for the specified time range
2024-09-10 12:25:43,597 [ERROR]: core_parameter.py(_run_diag:269) >> Error in e3sm_diags.driver.polar_driver
2024-09-10 12:25:43,745 [ERROR]: core_parameter.py(_run_diag:269) >> Error in e3sm_diags.driver.polar_driver
2024-09-10 12:25:51,055 [ERROR]: area_mean_time_series_driver.py(run_diag:139) >> No valid value for reference datasets available for the specified time range
2024-09-10 12:25:51,057 [ERROR]: area_mean_time_series_driver.py(run_diag:139) >> No valid value for reference datasets available for the specified time range
2024-09-10 12:25:51,077 [ERROR]: area_mean_time_series_driver.py(run_diag:139) >> No valid value for reference datasets available for the specified time range
2024-09-10 12:25:52,291 [ERROR]: core_parameter.py(_run_diag:269) >> Error in e3sm_diags.driver.annual_cycle_zonal_mean_driver
2024-09-10 12:25:52,388 [ERROR]: core_parameter.py(_run_diag:269) >> Error in e3sm_diags.driver.annual_cycle_zonal_mean_driver
2024-09-10 12:25:52,464 [ERROR]: core_parameter.py(_run_diag:269) >> Error in e3sm_diags.driver.annual_cycle_zonal_mean_driver
2024-09-10 12:25:53,745 [ERROR]: area_mean_time_series_driver.py(run_diag:139) >> No valid value for reference datasets available for the specified time range
2024-09-10 12:25:53,747 [ERROR]: area_mean_time_series_driver.py(run_diag:139) >> No valid value for reference datasets available for the specified time range
2024-09-10 12:25:53,748 [ERROR]: area_mean_time_series_driver.py(run_diag:139) >> No valid value for reference datasets available for the specified time range
2024-09-10 12:25:56,538 [ERROR]: area_mean_time_series_driver.py(run_diag:139) >> No valid value for reference datasets available for the specified time range
2024-09-10 12:25:56,539 [ERROR]: area_mean_time_series_driver.py(run_diag:139) >> No valid value for reference datasets available for the specified time range
2024-09-10 12:25:56,540 [ERROR]: area_mean_time_series_driver.py(run_diag:139) >> No valid value for reference datasets available for the specified time range
2024-09-10 12:25:56,729 [ERROR]: area_mean_time_series_driver.py(run_diag:139) >> No valid value for reference datasets available for the specified time range
2024-09-10 12:25:56,730 [ERROR]: area_mean_time_series_driver.py(run_diag:139) >> No valid value for reference datasets available for the specified time range
2024-09-10 12:25:56,731 [ERROR]: area_mean_time_series_driver.py(run_diag:139) >> No valid value for reference datasets available for the specified time range
2024-09-10 12:25:56,917 [ERROR]: area_mean_time_series_driver.py(run_diag:139) >> No valid value for reference datasets available for the specified time range
2024-09-10 12:25:56,919 [ERROR]: area_mean_time_series_driver.py(run_diag:139) >> No valid value for reference datasets available for the specified time range
2024-09-10 12:25:56,920 [ERROR]: area_mean_time_series_driver.py(run_diag:139) >> No valid value for reference datasets available for the specified time range
2024-09-10 12:25:57,139 [ERROR]: area_mean_time_series_driver.py(run_diag:139) >> No valid value for reference datasets available for the specified time range
2024-09-10 12:25:57,140 [ERROR]: area_mean_time_series_driver.py(run_diag:139) >> No valid value for reference datasets available for the specified time range
2024-09-10 12:25:57,141 [ERROR]: area_mean_time_series_driver.py(run_diag:139) >> No valid value for reference datasets available for the specified time range
2024-09-10 12:25:57,334 [ERROR]: area_mean_time_series_driver.py(run_diag:139) >> No valid value for reference datasets available for the specified time range
2024-09-10 12:25:57,336 [ERROR]: area_mean_time_series_driver.py(run_diag:139) >> No valid value for reference datasets available for the specified time range
2024-09-10 12:25:57,517 [ERROR]: area_mean_time_series_driver.py(run_diag:139) >> No valid value for reference datasets available for the specified time range
2024-09-10 12:25:57,519 [ERROR]: area_mean_time_series_driver.py(run_diag:139) >> No valid value for reference datasets available for the specified time range
2024-09-10 12:25:57,520 [ERROR]: area_mean_time_series_driver.py(run_diag:139) >> No valid value for reference datasets available for the specified time range
2024-09-10 12:25:59,090 [ERROR]: area_mean_time_series_driver.py(run_diag:139) >> No valid value for reference datasets available for the specified time range
2024-09-10 12:25:59,092 [ERROR]: area_mean_time_series_driver.py(run_diag:139) >> No valid value for reference datasets available for the specified time range
2024-09-10 12:26:01,707 [ERROR]: area_mean_time_series_driver.py(run_diag:139) >> No valid value for reference datasets available for the specified time range
2024-09-10 12:26:01,709 [ERROR]: area_mean_time_series_driver.py(run_diag:139) >> No valid value for reference datasets available for the specified time range
2024-09-10 12:26:04,298 [ERROR]: area_mean_time_series_driver.py(run_diag:139) >> No valid value for reference datasets available for the specified time range
2024-09-10 12:26:04,300 [ERROR]: area_mean_time_series_driver.py(run_diag:139) >> No valid value for reference datasets available for the specified time range
2024-09-10 12:26:04,427 [ERROR]: area_mean_time_series_driver.py(run_diag:139) >> No valid value for reference datasets available for the specified time range
2024-09-10 12:26:04,429 [ERROR]: area_mean_time_series_driver.py(run_diag:139) >> No valid value for reference datasets available for the specified time range
2024-09-10 12:26:04,554 [ERROR]: area_mean_time_series_driver.py(run_diag:139) >> No valid value for reference datasets available for the specified time range
2024-09-10 12:26:04,556 [ERROR]: area_mean_time_series_driver.py(run_diag:139) >> No valid value for reference datasets available for the specified time range
2024-09-10 12:26:04,682 [ERROR]: area_mean_time_series_driver.py(run_diag:139) >> No valid value for reference datasets available for the specified time range
2024-09-10 12:26:04,684 [ERROR]: area_mean_time_series_driver.py(run_diag:139) >> No valid value for reference datasets available for the specified time range
2024-09-10 12:26:04,818 [ERROR]: area_mean_time_series_driver.py(run_diag:139) >> No valid value for reference datasets available for the specified time range
2024-09-10 12:26:04,820 [ERROR]: area_mean_time_series_driver.py(run_diag:139) >> No valid value for reference datasets available for the specified time range
2024-09-10 12:26:04,983 [ERROR]: area_mean_time_series_driver.py(run_diag:139) >> No valid value for reference datasets available for the specified time range
2024-09-10 12:26:04,985 [ERROR]: area_mean_time_series_driver.py(run_diag:139) >> No valid value for reference datasets available for the specified time range
2024-09-10 12:26:05,069 [ERROR]: core_parameter.py(_run_diag:269) >> Error in e3sm_diags.driver.lat_lon_driver
2024-09-10 12:26:05,220 [ERROR]: core_parameter.py(_run_diag:269) >> Error in e3sm_diags.driver.lat_lon_driver
2024-09-10 12:26:05,368 [ERROR]: core_parameter.py(_run_diag:269) >> Error in e3sm_diags.driver.lat_lon_driver
2024-09-10 12:26:05,515 [ERROR]: core_parameter.py(_run_diag:269) >> Error in e3sm_diags.driver.lat_lon_driver
2024-09-10 12:26:05,663 [ERROR]: core_parameter.py(_run_diag:269) >> Error in e3sm_diags.driver.lat_lon_driver
2024-09-10 12:26:05,808 [ERROR]: core_parameter.py(_run_diag:269) >> Error in e3sm_diags.driver.lat_lon_driver
2024-09-10 12:26:05,955 [ERROR]: core_parameter.py(_run_diag:269) >> Error in e3sm_diags.driver.lat_lon_driver
2024-09-10 12:26:06,103 [ERROR]: core_parameter.py(_run_diag:269) >> Error in e3sm_diags.driver.lat_lon_driver
2024-09-10 12:26:06,299 [ERROR]: area_mean_time_series_driver.py(run_diag:139) >> No valid value for reference datasets available for the specified time range
2024-09-10 12:26:06,302 [ERROR]: area_mean_time_series_driver.py(run_diag:139) >> No valid value for reference datasets available for the specified time range
2024-09-10 12:26:06,349 [ERROR]: core_parameter.py(_run_diag:269) >> Error in e3sm_diags.driver.lat_lon_driver
2024-09-10 12:26:06,501 [ERROR]: core_parameter.py(_run_diag:269) >> Error in e3sm_diags.driver.lat_lon_driver
2024-09-10 12:26:06,653 [ERROR]: core_parameter.py(_run_diag:269) >> Error in e3sm_diags.driver.lat_lon_driver
2024-09-10 12:26:06,803 [ERROR]: core_parameter.py(_run_diag:269) >> Error in e3sm_diags.driver.lat_lon_driver
2024-09-10 12:26:06,956 [ERROR]: core_parameter.py(_run_diag:269) >> Error in e3sm_diags.driver.lat_lon_driver
2024-09-10 12:26:07,103 [ERROR]: core_parameter.py(_run_diag:269) >> Error in e3sm_diags.driver.lat_lon_driver
2024-09-10 12:26:07,250 [ERROR]: core_parameter.py(_run_diag:269) >> Error in e3sm_diags.driver.lat_lon_driver
2024-09-10 12:26:07,396 [ERROR]: core_parameter.py(_run_diag:269) >> Error in e3sm_diags.driver.lat_lon_driver
2024-09-10 12:26:08,898 [ERROR]: area_mean_time_series_driver.py(run_diag:139) >> No valid value for reference datasets available for the specified time range
2024-09-10 12:26:08,899 [ERROR]: area_mean_time_series_driver.py(run_diag:139) >> No valid value for reference datasets available for the specified time range
2024-09-10 12:26:11,476 [ERROR]: area_mean_time_series_driver.py(run_diag:139) >> No valid value for reference datasets available for the specified time range
2024-09-10 12:26:11,478 [ERROR]: area_mean_time_series_driver.py(run_diag:139) >> No valid value for reference datasets available for the specified time range
2024-09-10 12:26:11,649 [ERROR]: area_mean_time_series_driver.py(run_diag:139) >> No valid value for reference datasets available for the specified time range
2024-09-10 12:26:11,651 [ERROR]: area_mean_time_series_driver.py(run_diag:139) >> No valid value for reference datasets available for the specified time range
2024-09-10 12:26:11,798 [ERROR]: area_mean_time_series_driver.py(run_diag:139) >> No valid value for reference datasets available for the specified time range
2024-09-10 12:26:11,799 [ERROR]: area_mean_time_series_driver.py(run_diag:139) >> No valid value for reference datasets available for the specified time range
2024-09-10 12:26:11,924 [ERROR]: area_mean_time_series_driver.py(run_diag:139) >> No valid value for reference datasets available for the specified time range
2024-09-10 12:26:11,926 [ERROR]: area_mean_time_series_driver.py(run_diag:139) >> No valid value for reference datasets available for the specified time range
2024-09-10 12:26:12,068 [ERROR]: area_mean_time_series_driver.py(run_diag:139) >> No valid value for reference datasets available for the specified time range
2024-09-10 12:26:12,069 [ERROR]: area_mean_time_series_driver.py(run_diag:139) >> No valid value for reference datasets available for the specified time range
2024-09-10 12:26:12,194 [ERROR]: area_mean_time_series_driver.py(run_diag:139) >> No valid value for reference datasets available for the specified time range
2024-09-10 12:26:12,196 [ERROR]: area_mean_time_series_driver.py(run_diag:139) >> No valid value for reference datasets available for the specified time range
2024-09-10 12:26:13,537 [ERROR]: area_mean_time_series_driver.py(run_diag:139) >> No valid value for reference datasets available for the specified time range
2024-09-10 12:26:13,538 [ERROR]: area_mean_time_series_driver.py(run_diag:139) >> No valid value for reference datasets available for the specified time range
2024-09-10 12:26:16,125 [ERROR]: area_mean_time_series_driver.py(run_diag:139) >> No valid value for reference datasets available for the specified time range
2024-09-10 12:26:16,127 [ERROR]: area_mean_time_series_driver.py(run_diag:139) >> No valid value for reference datasets available for the specified time range
2024-09-10 12:26:18,756 [ERROR]: area_mean_time_series_driver.py(run_diag:139) >> No valid value for reference datasets available for the specified time range
2024-09-10 12:26:18,758 [ERROR]: area_mean_time_series_driver.py(run_diag:139) >> No valid value for reference datasets available for the specified time range
2024-09-10 12:26:18,917 [ERROR]: area_mean_time_series_driver.py(run_diag:139) >> No valid value for reference datasets available for the specified time range
2024-09-10 12:26:18,919 [ERROR]: area_mean_time_series_driver.py(run_diag:139) >> No valid value for reference datasets available for the specified time range
2024-09-10 12:26:19,030 [ERROR]: area_mean_time_series_driver.py(run_diag:139) >> No valid value for reference datasets available for the specified time range
2024-09-10 12:26:19,031 [ERROR]: area_mean_time_series_driver.py(run_diag:139) >> No valid value for reference datasets available for the specified time range
2024-09-10 12:26:19,151 [ERROR]: area_mean_time_series_driver.py(run_diag:139) >> No valid value for reference datasets available for the specified time range
2024-09-10 12:26:19,152 [ERROR]: area_mean_time_series_driver.py(run_diag:139) >> No valid value for reference datasets available for the specified time range
2024-09-10 12:26:19,273 [ERROR]: area_mean_time_series_driver.py(run_diag:139) >> No valid value for reference datasets available for the specified time range
2024-09-10 12:26:19,275 [ERROR]: area_mean_time_series_driver.py(run_diag:139) >> No valid value for reference datasets available for the specified time range
2024-09-10 12:26:19,393 [ERROR]: area_mean_time_series_driver.py(run_diag:139) >> No valid value for reference datasets available for the specified time range
2024-09-10 12:26:19,395 [ERROR]: area_mean_time_series_driver.py(run_diag:139) >> No valid value for reference datasets available for the specified time range
2024-09-10 12:26:20,161 [ERROR]: core_parameter.py(_run_diag:269) >> Error in e3sm_diags.driver.annual_cycle_zonal_mean_driver
2024-09-10 12:26:20,240 [ERROR]: core_parameter.py(_run_diag:269) >> Error in e3sm_diags.driver.annual_cycle_zonal_mean_driver
2024-09-10 12:26:20,315 [ERROR]: core_parameter.py(_run_diag:269) >> Error in e3sm_diags.driver.annual_cycle_zonal_mean_driver
2024-09-10 12:26:20,393 [ERROR]: core_parameter.py(_run_diag:269) >> Error in e3sm_diags.driver.annual_cycle_zonal_mean_driver
2024-09-10 12:26:20,858 [ERROR]: area_mean_time_series_driver.py(run_diag:139) >> No valid value for reference datasets available for the specified time range
2024-09-10 12:26:23,627 [ERROR]: area_mean_time_series_driver.py(run_diag:139) >> No valid value for reference datasets available for the specified time range
2024-09-10 12:26:24,685 [ERROR]: core_parameter.py(_run_diag:269) >> Error in e3sm_diags.driver.lat_lon_driver
2024-09-10 12:26:24,837 [ERROR]: core_parameter.py(_run_diag:269) >> Error in e3sm_diags.driver.lat_lon_driver
2024-09-10 12:26:24,999 [ERROR]: core_parameter.py(_run_diag:269) >> Error in e3sm_diags.driver.lat_lon_driver
2024-09-10 12:26:25,162 [ERROR]: core_parameter.py(_run_diag:269) >> Error in e3sm_diags.driver.lat_lon_driver
2024-09-10 12:26:25,317 [ERROR]: core_parameter.py(_run_diag:269) >> Error in e3sm_diags.driver.lat_lon_driver
2024-09-10 12:26:25,470 [ERROR]: core_parameter.py(_run_diag:269) >> Error in e3sm_diags.driver.lat_lon_driver
2024-09-10 12:26:25,620 [ERROR]: core_parameter.py(_run_diag:269) >> Error in e3sm_diags.driver.lat_lon_driver
2024-09-10 12:26:25,773 [ERROR]: core_parameter.py(_run_diag:269) >> Error in e3sm_diags.driver.lat_lon_driver
2024-09-10 12:26:25,927 [ERROR]: core_parameter.py(_run_diag:269) >> Error in e3sm_diags.driver.lat_lon_driver
2024-09-10 12:26:26,127 [ERROR]: core_parameter.py(_run_diag:269) >> Error in e3sm_diags.driver.lat_lon_driver
2024-09-10 12:26:26,282 [ERROR]: core_parameter.py(_run_diag:269) >> Error in e3sm_diags.driver.lat_lon_driver
2024-09-10 12:26:26,360 [ERROR]: area_mean_time_series_driver.py(run_diag:139) >> No valid value for reference datasets available for the specified time range
2024-09-10 12:26:26,436 [ERROR]: core_parameter.py(_run_diag:269) >> Error in e3sm_diags.driver.lat_lon_driver
2024-09-10 12:26:26,496 [ERROR]: area_mean_time_series_driver.py(run_diag:139) >> No valid value for reference datasets available for the specified time range
2024-09-10 12:26:26,645 [ERROR]: area_mean_time_series_driver.py(run_diag:139) >> No valid value for reference datasets available for the specified time range
2024-09-10 12:26:26,795 [ERROR]: area_mean_time_series_driver.py(run_diag:139) >> No valid value for reference datasets available for the specified time range
2024-09-10 12:26:26,930 [ERROR]: area_mean_time_series_driver.py(run_diag:139) >> No valid value for reference datasets available for the specified time range
2024-09-10 12:26:27,072 [ERROR]: area_mean_time_series_driver.py(run_diag:139) >> No valid value for reference datasets available for the specified time range
2024-09-10 12:26:28,421 [ERROR]: area_mean_time_series_driver.py(run_diag:139) >> No valid value for reference datasets available for the specified time range
2024-09-10 12:26:31,231 [ERROR]: area_mean_time_series_driver.py(run_diag:139) >> No valid value for reference datasets available for the specified time range
2024-09-10 12:26:33,977 [ERROR]: area_mean_time_series_driver.py(run_diag:139) >> No valid value for reference datasets available for the specified time range
2024-09-10 12:26:34,142 [ERROR]: area_mean_time_series_driver.py(run_diag:139) >> No valid value for reference datasets available for the specified time range
2024-09-10 12:26:34,275 [ERROR]: area_mean_time_series_driver.py(run_diag:139) >> No valid value for reference datasets available for the specified time range
2024-09-10 12:26:34,426 [ERROR]: area_mean_time_series_driver.py(run_diag:139) >> No valid value for reference datasets available for the specified time range
2024-09-10 12:26:34,550 [ERROR]: area_mean_time_series_driver.py(run_diag:139) >> No valid value for reference datasets available for the specified time range
2024-09-10 12:26:34,693 [ERROR]: area_mean_time_series_driver.py(run_diag:139) >> No valid value for reference datasets available for the specified time range
2024-09-10 12:26:36,263 [ERROR]: area_mean_time_series_driver.py(run_diag:139) >> No valid value for reference datasets available for the specified time range
2024-09-10 12:26:38,848 [ERROR]: area_mean_time_series_driver.py(run_diag:139) >> No valid value for reference datasets available for the specified time range
2024-09-10 12:26:41,505 [ERROR]: area_mean_time_series_driver.py(run_diag:139) >> No valid value for reference datasets available for the specified time range
2024-09-10 12:26:41,682 [ERROR]: area_mean_time_series_driver.py(run_diag:139) >> No valid value for reference datasets available for the specified time range
2024-09-10 12:26:41,801 [ERROR]: area_mean_time_series_driver.py(run_diag:139) >> No valid value for reference datasets available for the specified time range
2024-09-10 12:26:41,933 [ERROR]: area_mean_time_series_driver.py(run_diag:139) >> No valid value for reference datasets available for the specified time range
2024-09-10 12:26:42,059 [ERROR]: area_mean_time_series_driver.py(run_diag:139) >> No valid value for reference datasets available for the specified time range
2024-09-10 12:26:42,180 [ERROR]: area_mean_time_series_driver.py(run_diag:139) >> No valid value for reference datasets available for the specified time range
2024-09-10 12:26:43,518 [ERROR]: area_mean_time_series_driver.py(run_diag:139) >> No valid value for reference datasets available for the specified time range
2024-09-10 12:26:46,133 [ERROR]: area_mean_time_series_driver.py(run_diag:139) >> No valid value for reference datasets available for the specified time range
2024-09-10 12:26:48,811 [ERROR]: area_mean_time_series_driver.py(run_diag:139) >> No valid value for reference datasets available for the specified time range
2024-09-10 12:26:48,959 [ERROR]: area_mean_time_series_driver.py(run_diag:139) >> No valid value for reference datasets available for the specified time range
2024-09-10 12:26:49,071 [ERROR]: area_mean_time_series_driver.py(run_diag:139) >> No valid value for reference datasets available for the specified time range
2024-09-10 12:26:49,206 [ERROR]: area_mean_time_series_driver.py(run_diag:139) >> No valid value for reference datasets available for the specified time range
2024-09-10 12:26:49,318 [ERROR]: area_mean_time_series_driver.py(run_diag:139) >> No valid value for reference datasets available for the specified time range
2024-09-10 12:26:49,470 [ERROR]: area_mean_time_series_driver.py(run_diag:139) >> No valid value for reference datasets available for the specified time range
2024-09-10 12:26:50,977 [ERROR]: core_parameter.py(_run_diag:269) >> Error in e3sm_diags.driver.polar_driver
2024-09-10 12:26:51,134 [ERROR]: core_parameter.py(_run_diag:269) >> Error in e3sm_diags.driver.polar_driver
2024-09-10 12:27:02,599 [ERROR]: core_parameter.py(_run_diag:269) >> Error in e3sm_diags.driver.polar_driver
2024-09-10 12:27:02,791 [ERROR]: core_parameter.py(_run_diag:269) >> Error in e3sm_diags.driver.polar_driver
2024-09-10 12:27:14,136 [ERROR]: core_parameter.py(_run_diag:269) >> Error in e3sm_diags.driver.polar_driver
2024-09-10 12:27:14,284 [ERROR]: core_parameter.py(_run_diag:269) >> Error in e3sm_diags.driver.polar_driver
2024-09-10 12:27:14,542 [ERROR]: core_parameter.py(_run_diag:269) >> Error in e3sm_diags.driver.polar_driver
2024-09-10 12:27:14,696 [ERROR]: core_parameter.py(_run_diag:269) >> Error in e3sm_diags.driver.polar_driver
2024-09-10 12:27:14,776 [ERROR]: core_parameter.py(_run_diag:269) >> Error in e3sm_diags.driver.zonal_mean_xy_driver
2024-09-10 12:27:14,851 [ERROR]: core_parameter.py(_run_diag:269) >> Error in e3sm_diags.driver.zonal_mean_xy_driver
2024-09-10 12:27:14,923 [ERROR]: core_parameter.py(_run_diag:269) >> Error in e3sm_diags.driver.zonal_mean_xy_driver
2024-09-10 12:27:14,998 [ERROR]: core_parameter.py(_run_diag:269) >> Error in e3sm_diags.driver.zonal_mean_xy_driver
2024-09-10 12:27:15,074 [ERROR]: core_parameter.py(_run_diag:269) >> Error in e3sm_diags.driver.zonal_mean_xy_driver
2024-09-10 12:27:15,149 [ERROR]: core_parameter.py(_run_diag:269) >> Error in e3sm_diags.driver.zonal_mean_xy_driver
2024-09-10 12:27:15,221 [ERROR]: core_parameter.py(_run_diag:269) >> Error in e3sm_diags.driver.zonal_mean_xy_driver
2024-09-10 12:27:15,294 [ERROR]: core_parameter.py(_run_diag:269) >> Error in e3sm_diags.driver.zonal_mean_xy_driver
2024-09-10 12:27:24,530 [ERROR]: general.py(save_transient_variables_to_netcdf:318) >> Could not write variable level
2024-09-10 12:27:24,544 [ERROR]: general.py(save_transient_variables_to_netcdf:318) >> Could not write variable level
2024-09-10 12:27:25,485 [ERROR]: core_parameter.py(_run_diag:269) >> Error in e3sm_diags.driver.area_mean_time_series_driver
2024-09-10 12:27:33,552 [ERROR]: core_parameter.py(_run_diag:269) >> Error in e3sm_diags.driver.zonal_mean_xy_driver
2024-09-10 12:27:33,632 [ERROR]: core_parameter.py(_run_diag:269) >> Error in e3sm_diags.driver.zonal_mean_xy_driver
2024-09-10 12:27:33,707 [ERROR]: core_parameter.py(_run_diag:269) >> Error in e3sm_diags.driver.zonal_mean_xy_driver
2024-09-10 12:27:33,783 [ERROR]: core_parameter.py(_run_diag:269) >> Error in e3sm_diags.driver.zonal_mean_xy_driver
2024-09-10 12:27:33,859 [ERROR]: core_parameter.py(_run_diag:269) >> Error in e3sm_diags.driver.zonal_mean_xy_driver
2024-09-10 12:27:33,938 [ERROR]: core_parameter.py(_run_diag:269) >> Error in e3sm_diags.driver.zonal_mean_xy_driver
2024-09-10 12:27:34,013 [ERROR]: core_parameter.py(_run_diag:269) >> Error in e3sm_diags.driver.zonal_mean_xy_driver
2024-09-10 12:27:34,087 [ERROR]: core_parameter.py(_run_diag:269) >> Error in e3sm_diags.driver.zonal_mean_xy_driver
2024-09-10 12:27:34,164 [ERROR]: core_parameter.py(_run_diag:269) >> Error in e3sm_diags.driver.zonal_mean_xy_driver
2024-09-10 12:27:34,239 [ERROR]: core_parameter.py(_run_diag:269) >> Error in e3sm_diags.driver.zonal_mean_xy_driver
2024-09-10 12:27:34,316 [ERROR]: core_parameter.py(_run_diag:269) >> Error in e3sm_diags.driver.zonal_mean_xy_driver
2024-09-10 12:27:34,391 [ERROR]: core_parameter.py(_run_diag:269) >> Error in e3sm_diags.driver.zonal_mean_xy_driver
2024-09-10 12:27:34,468 [ERROR]: core_parameter.py(_run_diag:269) >> Error in e3sm_diags.driver.zonal_mean_xy_driver
2024-09-10 12:27:34,543 [ERROR]: core_parameter.py(_run_diag:269) >> Error in e3sm_diags.driver.zonal_mean_xy_driver
2024-09-10 12:27:34,619 [ERROR]: core_parameter.py(_run_diag:269) >> Error in e3sm_diags.driver.zonal_mean_xy_driver
2024-09-10 12:27:34,692 [ERROR]: core_parameter.py(_run_diag:269) >> Error in e3sm_diags.driver.zonal_mean_xy_driver
2024-09-10 12:27:34,767 [ERROR]: core_parameter.py(_run_diag:269) >> Error in e3sm_diags.driver.zonal_mean_xy_driver
2024-09-10 12:27:34,845 [ERROR]: core_parameter.py(_run_diag:269) >> Error in e3sm_diags.driver.zonal_mean_xy_driver
2024-09-10 12:27:34,923 [ERROR]: core_parameter.py(_run_diag:269) >> Error in e3sm_diags.driver.zonal_mean_xy_driver
2024-09-10 12:27:34,999 [ERROR]: core_parameter.py(_run_diag:269) >> Error in e3sm_diags.driver.zonal_mean_xy_driver
2024-09-10 12:27:35,073 [ERROR]: core_parameter.py(_run_diag:269) >> Error in e3sm_diags.driver.zonal_mean_xy_driver
2024-09-10 12:27:35,152 [ERROR]: core_parameter.py(_run_diag:269) >> Error in e3sm_diags.driver.zonal_mean_xy_driver
2024-09-10 12:27:35,229 [ERROR]: core_parameter.py(_run_diag:269) >> Error in e3sm_diags.driver.zonal_mean_xy_driver
2024-09-10 12:27:35,306 [ERROR]: core_parameter.py(_run_diag:269) >> Error in e3sm_diags.driver.zonal_mean_xy_driver
2024-09-10 12:27:35,382 [ERROR]: core_parameter.py(_run_diag:269) >> Error in e3sm_diags.driver.zonal_mean_xy_driver
2024-09-10 12:27:35,456 [ERROR]: core_parameter.py(_run_diag:269) >> Error in e3sm_diags.driver.zonal_mean_xy_driver
2024-09-10 12:27:35,530 [ERROR]: core_parameter.py(_run_diag:269) >> Error in e3sm_diags.driver.zonal_mean_xy_driver
2024-09-10 12:27:35,605 [ERROR]: core_parameter.py(_run_diag:269) >> Error in e3sm_diags.driver.zonal_mean_xy_driver
2024-09-10 12:27:53,129 [ERROR]: core_parameter.py(_run_diag:269) >> Error in e3sm_diags.driver.zonal_mean_xy_driver
2024-09-10 12:27:53,298 [ERROR]: core_parameter.py(_run_diag:269) >> Error in e3sm_diags.driver.zonal_mean_xy_driver
2024-09-10 12:27:53,372 [ERROR]: core_parameter.py(_run_diag:269) >> Error in e3sm_diags.driver.zonal_mean_xy_driver
2024-09-10 12:27:53,445 [ERROR]: core_parameter.py(_run_diag:269) >> Error in e3sm_diags.driver.zonal_mean_xy_driver
2024-09-10 12:27:53,517 [ERROR]: core_parameter.py(_run_diag:269) >> Error in e3sm_diags.driver.zonal_mean_xy_driver
2024-09-10 12:27:53,589 [ERROR]: core_parameter.py(_run_diag:269) >> Error in e3sm_diags.driver.zonal_mean_xy_driver
2024-09-10 12:27:53,660 [ERROR]: core_parameter.py(_run_diag:269) >> Error in e3sm_diags.driver.zonal_mean_xy_driver
2024-09-10 12:27:53,731 [ERROR]: core_parameter.py(_run_diag:269) >> Error in e3sm_diags.driver.zonal_mean_xy_driver
2024-09-10 12:27:53,802 [ERROR]: core_parameter.py(_run_diag:269) >> Error in e3sm_diags.driver.zonal_mean_xy_driver
2024-09-10 12:27:53,873 [ERROR]: core_parameter.py(_run_diag:269) >> Error in e3sm_diags.driver.zonal_mean_xy_driver
2024-09-10 12:27:53,945 [ERROR]: core_parameter.py(_run_diag:269) >> Error in e3sm_diags.driver.zonal_mean_xy_driver
2024-09-10 12:27:54,016 [ERROR]: core_parameter.py(_run_diag:269) >> Error in e3sm_diags.driver.zonal_mean_xy_driver
2024-09-10 12:27:58,268 [ERROR]: core_parameter.py(_run_diag:269) >> Error in e3sm_diags.driver.polar_driver
2024-09-10 12:27:58,438 [ERROR]: core_parameter.py(_run_diag:269) >> Error in e3sm_diags.driver.polar_driver
2024-09-10 12:27:58,605 [ERROR]: core_parameter.py(_run_diag:269) >> Error in e3sm_diags.driver.polar_driver
2024-09-10 12:27:58,769 [ERROR]: core_parameter.py(_run_diag:269) >> Error in e3sm_diags.driver.polar_driver
2024-09-10 12:28:08,566 [ERROR]: core_parameter.py(_run_diag:269) >> Error in e3sm_diags.driver.polar_driver
2024-09-10 12:28:08,716 [ERROR]: core_parameter.py(_run_diag:269) >> Error in e3sm_diags.driver.polar_driver
2024-09-10 12:28:08,863 [ERROR]: core_parameter.py(_run_diag:269) >> Error in e3sm_diags.driver.polar_driver
2024-09-10 12:28:09,009 [ERROR]: core_parameter.py(_run_diag:269) >> Error in e3sm_diags.driver.polar_driver
2024-09-10 12:28:09,155 [ERROR]: core_parameter.py(_run_diag:269) >> Error in e3sm_diags.driver.polar_driver
2024-09-10 12:28:09,301 [ERROR]: core_parameter.py(_run_diag:269) >> Error in e3sm_diags.driver.polar_driver
2024-09-10 12:28:09,467 [ERROR]: core_parameter.py(_run_diag:269) >> Error in e3sm_diags.driver.polar_driver
2024-09-10 12:28:09,619 [ERROR]: core_parameter.py(_run_diag:269) >> Error in e3sm_diags.driver.polar_driver
2024-09-10 12:28:15,637 [ERROR]: core_parameter.py(_run_diag:269) >> Error in e3sm_diags.driver.zonal_mean_xy_driver
2024-09-10 12:28:15,710 [ERROR]: core_parameter.py(_run_diag:269) >> Error in e3sm_diags.driver.zonal_mean_xy_driver
2024-09-10 12:28:15,782 [ERROR]: core_parameter.py(_run_diag:269) >> Error in e3sm_diags.driver.zonal_mean_xy_driver
2024-09-10 12:28:15,853 [ERROR]: core_parameter.py(_run_diag:269) >> Error in e3sm_diags.driver.zonal_mean_xy_driver
2024-09-10 12:28:15,926 [ERROR]: core_parameter.py(_run_diag:269) >> Error in e3sm_diags.driver.zonal_mean_xy_driver
2024-09-10 12:28:15,999 [ERROR]: core_parameter.py(_run_diag:269) >> Error in e3sm_diags.driver.zonal_mean_xy_driver
2024-09-10 12:28:16,071 [ERROR]: core_parameter.py(_run_diag:269) >> Error in e3sm_diags.driver.zonal_mean_xy_driver
2024-09-10 12:28:16,144 [ERROR]: core_parameter.py(_run_diag:269) >> Error in e3sm_diags.driver.zonal_mean_xy_driver
2024-09-10 12:28:16,219 [ERROR]: core_parameter.py(_run_diag:269) >> Error in e3sm_diags.driver.zonal_mean_xy_driver
2024-09-10 12:28:16,292 [ERROR]: core_parameter.py(_run_diag:269) >> Error in e3sm_diags.driver.zonal_mean_xy_driver
2024-09-10 12:28:16,366 [ERROR]: core_parameter.py(_run_diag:269) >> Error in e3sm_diags.driver.zonal_mean_xy_driver
2024-09-10 12:28:16,440 [ERROR]: core_parameter.py(_run_diag:269) >> Error in e3sm_diags.driver.zonal_mean_xy_driver
2024-09-10 12:28:17,385 [ERROR]: core_parameter.py(_run_diag:269) >> Error in e3sm_diags.driver.zonal_mean_xy_driver
2024-09-10 12:28:17,459 [ERROR]: core_parameter.py(_run_diag:269) >> Error in e3sm_diags.driver.zonal_mean_xy_driver
2024-09-10 12:28:41,151 [ERROR]: core_parameter.py(_run_diag:269) >> Error in e3sm_diags.driver.annual_cycle_zonal_mean_driver
2024-09-10 12:28:41,224 [ERROR]: core_parameter.py(_run_diag:269) >> Error in e3sm_diags.driver.annual_cycle_zonal_mean_driver
2024-09-10 12:28:48,350 [ERROR]: core_parameter.py(_run_diag:269) >> Error in e3sm_diags.driver.lat_lon_driver
2024-09-10 12:28:49,291 [ERROR]: core_parameter.py(_run_diag:269) >> Error in e3sm_diags.driver.lat_lon_driver
2024-09-10 12:29:20,655 [ERROR]: core_parameter.py(_run_diag:269) >> Error in e3sm_diags.driver.annual_cycle_zonal_mean_driver
2024-09-10 12:29:20,728 [ERROR]: core_parameter.py(_run_diag:269) >> Error in e3sm_diags.driver.annual_cycle_zonal_mean_driver
2024-09-10 12:29:20,800 [ERROR]: core_parameter.py(_run_diag:269) >> Error in e3sm_diags.driver.annual_cycle_zonal_mean_driver
2024-09-10 12:29:20,872 [ERROR]: core_parameter.py(_run_diag:269) >> Error in e3sm_diags.driver.annual_cycle_zonal_mean_driver
2024-09-10 12:29:20,948 [ERROR]: core_parameter.py(_run_diag:269) >> Error in e3sm_diags.driver.annual_cycle_zonal_mean_driver
2024-09-10 12:29:21,021 [ERROR]: core_parameter.py(_run_diag:269) >> Error in e3sm_diags.driver.annual_cycle_zonal_mean_driver
2024-09-10 12:29:21,092 [ERROR]: core_parameter.py(_run_diag:269) >> Error in e3sm_diags.driver.annual_cycle_zonal_mean_driver
2024-09-10 12:29:21,163 [ERROR]: core_parameter.py(_run_diag:269) >> Error in e3sm_diags.driver.annual_cycle_zonal_mean_driver
2024-09-10 12:29:21,234 [ERROR]: core_parameter.py(_run_diag:269) >> Error in e3sm_diags.driver.annual_cycle_zonal_mean_driver
2024-09-10 12:29:21,305 [ERROR]: core_parameter.py(_run_diag:269) >> Error in e3sm_diags.driver.annual_cycle_zonal_mean_driver
2024-09-10 12:29:21,376 [ERROR]: core_parameter.py(_run_diag:269) >> Error in e3sm_diags.driver.annual_cycle_zonal_mean_driver
2024-09-10 12:29:21,448 [ERROR]: core_parameter.py(_run_diag:269) >> Error in e3sm_diags.driver.annual_cycle_zonal_mean_driver
2024-09-10 12:29:29,584 [ERROR]: run.py(run_diags:91) >> Error traceback:
AttributeError: 'NoneType' object has no attribute 'id'
AttributeError: 'TransientVariable' object has no attribute 'units'
CDMS I/O error: Determining type of file /global/cfs/cdirs/e3sm/diagnostics/observations/Atm/climatology/20210115_MERRA2; must specify dictionary (control) file
OSError: No file found for  and ANN in /global/cfs/cdirs/e3sm/diagnostics/observations/Atm/climatology
OSError: No file found for  and JJA in /global/cfs/cdirs/e3sm/diagnostics/observations/Atm/climatology
OSError: No file found for HadISST and ANN in /global/cfs/cdirs/e3sm/diagnostics/observations/Atm/climatology
OSError: No file found for HadISST and JJA in /global/cfs/cdirs/e3sm/diagnostics/observations/Atm/climatology
    raise IOError(
    raise RuntimeErrorError(msg)
    raise RuntimeError(msg)
RuntimeError: Invalid year range specified for test/reference time series data: start_year=51<1979=var_start_yr
RuntimeError: Invalid year range specified for test/reference time series data: start_year=51<1980=var_start_yr
RuntimeError: Invalid year range specified for test/reference time series data: start_year=51<2001=var_start_yr
RuntimeError: Neither does _ABURDENBC nor the variables in [('ABURDENBC',)] exist in the file file:///global/cfs/cdirs/e3sm/e3sm_diags/postprocessed_e3sm_v2_data_for_e3sm_diags/20210528.v2rc3e.piControl.ne30pg2_EC30to60E2r2.chrysalis/climatology/rgr/20210528.v2rc3e.piControl.ne30pg2_EC30to60E2r2.chrysalis_ANN_005101_006012_climo.nc.
RuntimeError: Neither does _ABURDENBC nor the variables in [('ABURDENBC',)] exist in the file file:///global/cfs/cdirs/e3sm/e3sm_diags/postprocessed_e3sm_v2_data_for_e3sm_diags/20210528.v2rc3e.piControl.ne30pg2_EC30to60E2r2.chrysalis/climatology/rgr/20210528.v2rc3e.piControl.ne30pg2_EC30to60E2r2.chrysalis_JJA_005106_006008_climo.nc.
RuntimeError: Neither does _ABURDENDUST nor the variables in [('ABURDENDUST',)] exist in the file file:///global/cfs/cdirs/e3sm/e3sm_diags/postprocessed_e3sm_v2_data_for_e3sm_diags/20210528.v2rc3e.piControl.ne30pg2_EC30to60E2r2.chrysalis/climatology/rgr/20210528.v2rc3e.piControl.ne30pg2_EC30to60E2r2.chrysalis_ANN_005101_006012_climo.nc.
RuntimeError: Neither does _ABURDENDUST nor the variables in [('ABURDENDUST',)] exist in the file file:///global/cfs/cdirs/e3sm/e3sm_diags/postprocessed_e3sm_v2_data_for_e3sm_diags/20210528.v2rc3e.piControl.ne30pg2_EC30to60E2r2.chrysalis/climatology/rgr/20210528.v2rc3e.piControl.ne30pg2_EC30to60E2r2.chrysalis_JJA_005106_006008_climo.nc.
RuntimeError: Neither does _ABURDENPOM nor the variables in [('ABURDENPOM',)] exist in the file file:///global/cfs/cdirs/e3sm/e3sm_diags/postprocessed_e3sm_v2_data_for_e3sm_diags/20210528.v2rc3e.piControl.ne30pg2_EC30to60E2r2.chrysalis/climatology/rgr/20210528.v2rc3e.piControl.ne30pg2_EC30to60E2r2.chrysalis_ANN_005101_006012_climo.nc.
RuntimeError: Neither does _ABURDENPOM nor the variables in [('ABURDENPOM',)] exist in the file file:///global/cfs/cdirs/e3sm/e3sm_diags/postprocessed_e3sm_v2_data_for_e3sm_diags/20210528.v2rc3e.piControl.ne30pg2_EC30to60E2r2.chrysalis/climatology/rgr/20210528.v2rc3e.piControl.ne30pg2_EC30to60E2r2.chrysalis_JJA_005106_006008_climo.nc.
RuntimeError: Neither does _ABURDENSEASALT nor the variables in [('ABURDENSEASALT',)] exist in the file file:///global/cfs/cdirs/e3sm/e3sm_diags/postprocessed_e3sm_v2_data_for_e3sm_diags/20210528.v2rc3e.piControl.ne30pg2_EC30to60E2r2.chrysalis/climatology/rgr/20210528.v2rc3e.piControl.ne30pg2_EC30to60E2r2.chrysalis_ANN_005101_006012_climo.nc.
RuntimeError: Neither does _ABURDENSEASALT nor the variables in [('ABURDENSEASALT',)] exist in the file file:///global/cfs/cdirs/e3sm/e3sm_diags/postprocessed_e3sm_v2_data_for_e3sm_diags/20210528.v2rc3e.piControl.ne30pg2_EC30to60E2r2.chrysalis/climatology/rgr/20210528.v2rc3e.piControl.ne30pg2_EC30to60E2r2.chrysalis_JJA_005106_006008_climo.nc.
RuntimeError: Neither does _ABURDENSO4 nor the variables in [('ABURDENSO4',)] exist in the file file:///global/cfs/cdirs/e3sm/e3sm_diags/postprocessed_e3sm_v2_data_for_e3sm_diags/20210528.v2rc3e.piControl.ne30pg2_EC30to60E2r2.chrysalis/climatology/rgr/20210528.v2rc3e.piControl.ne30pg2_EC30to60E2r2.chrysalis_ANN_005101_006012_climo.nc.
RuntimeError: Neither does _ABURDENSO4 nor the variables in [('ABURDENSO4',)] exist in the file file:///global/cfs/cdirs/e3sm/e3sm_diags/postprocessed_e3sm_v2_data_for_e3sm_diags/20210528.v2rc3e.piControl.ne30pg2_EC30to60E2r2.chrysalis/climatology/rgr/20210528.v2rc3e.piControl.ne30pg2_EC30to60E2r2.chrysalis_JJA_005106_006008_climo.nc.
RuntimeError: Neither does _ABURDENSO4_STR nor the variables in [('ABURDENSO4_STR',)] exist in the file file:///global/cfs/cdirs/e3sm/e3sm_diags/postprocessed_e3sm_v2_data_for_e3sm_diags/20210528.v2rc3e.piControl.ne30pg2_EC30to60E2r2.chrysalis/climatology/rgr/20210528.v2rc3e.piControl.ne30pg2_EC30to60E2r2.chrysalis_ANN_005101_006012_climo.nc.
RuntimeError: Neither does _ABURDENSO4_STR nor the variables in [('ABURDENSO4_STR',)] exist in the file file:///global/cfs/cdirs/e3sm/e3sm_diags/postprocessed_e3sm_v2_data_for_e3sm_diags/20210528.v2rc3e.piControl.ne30pg2_EC30to60E2r2.chrysalis/climatology/rgr/20210528.v2rc3e.piControl.ne30pg2_EC30to60E2r2.chrysalis_JJA_005106_006008_climo.nc.
RuntimeError: Neither does _ABURDENSO4_TRO nor the variables in [('ABURDENSO4_TRO',)] exist in the file file:///global/cfs/cdirs/e3sm/e3sm_diags/postprocessed_e3sm_v2_data_for_e3sm_diags/20210528.v2rc3e.piControl.ne30pg2_EC30to60E2r2.chrysalis/climatology/rgr/20210528.v2rc3e.piControl.ne30pg2_EC30to60E2r2.chrysalis_ANN_005101_006012_climo.nc.
RuntimeError: Neither does _ABURDENSO4_TRO nor the variables in [('ABURDENSO4_TRO',)] exist in the file file:///global/cfs/cdirs/e3sm/e3sm_diags/postprocessed_e3sm_v2_data_for_e3sm_diags/20210528.v2rc3e.piControl.ne30pg2_EC30to60E2r2.chrysalis/climatology/rgr/20210528.v2rc3e.piControl.ne30pg2_EC30to60E2r2.chrysalis_JJA_005106_006008_climo.nc.
RuntimeError: Neither does _ABURDENSOA nor the variables in [('ABURDENSOA',)] exist in the file file:///global/cfs/cdirs/e3sm/e3sm_diags/postprocessed_e3sm_v2_data_for_e3sm_diags/20210528.v2rc3e.piControl.ne30pg2_EC30to60E2r2.chrysalis/climatology/rgr/20210528.v2rc3e.piControl.ne30pg2_EC30to60E2r2.chrysalis_ANN_005101_006012_climo.nc.
RuntimeError: Neither does _ABURDENSOA nor the variables in [('ABURDENSOA',)] exist in the file file:///global/cfs/cdirs/e3sm/e3sm_diags/postprocessed_e3sm_v2_data_for_e3sm_diags/20210528.v2rc3e.piControl.ne30pg2_EC30to60E2r2.chrysalis/climatology/rgr/20210528.v2rc3e.piControl.ne30pg2_EC30to60E2r2.chrysalis_JJA_005106_006008_climo.nc.
RuntimeError: Neither does AODMOM nor the variables in [('AODMOM',)] exist in the file file:///global/cfs/cdirs/e3sm/e3sm_diags/postprocessed_e3sm_v2_data_for_e3sm_diags/20210528.v2rc3e.piControl.ne30pg2_EC30to60E2r2.chrysalis/climatology/rgr/20210528.v2rc3e.piControl.ne30pg2_EC30to60E2r2.chrysalis_01_005101_006001_climo.nc.
RuntimeError: Neither does AODMOM nor the variables in [('AODMOM',)] exist in the file file:///global/cfs/cdirs/e3sm/e3sm_diags/postprocessed_e3sm_v2_data_for_e3sm_diags/20210528.v2rc3e.piControl.ne30pg2_EC30to60E2r2.chrysalis/climatology/rgr/20210528.v2rc3e.piControl.ne30pg2_EC30to60E2r2.chrysalis_ANN_005101_006012_climo.nc.
RuntimeError: Neither does AODMOM nor the variables in [('AODMOM',)] exist in the file file:///global/cfs/cdirs/e3sm/e3sm_diags/postprocessed_e3sm_v2_data_for_e3sm_diags/20210528.v2rc3e.piControl.ne30pg2_EC30to60E2r2.chrysalis/climatology/rgr/20210528.v2rc3e.piControl.ne30pg2_EC30to60E2r2.chrysalis_JJA_005106_006008_climo.nc.
RuntimeError: Neither does AODSO4_STR nor the variables in [('AODSO4_STR',)] exist in the file file:///global/cfs/cdirs/e3sm/e3sm_diags/postprocessed_e3sm_v2_data_for_e3sm_diags/20210528.v2rc3e.piControl.ne30pg2_EC30to60E2r2.chrysalis/climatology/rgr/20210528.v2rc3e.piControl.ne30pg2_EC30to60E2r2.chrysalis_01_005101_006001_climo.nc.
RuntimeError: Neither does AODSO4_STR nor the variables in [('AODSO4_STR',)] exist in the file file:///global/cfs/cdirs/e3sm/e3sm_diags/postprocessed_e3sm_v2_data_for_e3sm_diags/20210528.v2rc3e.piControl.ne30pg2_EC30to60E2r2.chrysalis/climatology/rgr/20210528.v2rc3e.piControl.ne30pg2_EC30to60E2r2.chrysalis_ANN_005101_006012_climo.nc.
RuntimeError: Neither does AODSO4_STR nor the variables in [('AODSO4_STR',)] exist in the file file:///global/cfs/cdirs/e3sm/e3sm_diags/postprocessed_e3sm_v2_data_for_e3sm_diags/20210528.v2rc3e.piControl.ne30pg2_EC30to60E2r2.chrysalis/climatology/rgr/20210528.v2rc3e.piControl.ne30pg2_EC30to60E2r2.chrysalis_JJA_005106_006008_climo.nc.
RuntimeError: Neither does AODSO4_TRO nor the variables in [('AODSO4_TRO',)] exist in the file file:///global/cfs/cdirs/e3sm/e3sm_diags/postprocessed_e3sm_v2_data_for_e3sm_diags/20210528.v2rc3e.piControl.ne30pg2_EC30to60E2r2.chrysalis/climatology/rgr/20210528.v2rc3e.piControl.ne30pg2_EC30to60E2r2.chrysalis_01_005101_006001_climo.nc.
RuntimeError: Neither does AODSO4_TRO nor the variables in [('AODSO4_TRO',)] exist in the file file:///global/cfs/cdirs/e3sm/e3sm_diags/postprocessed_e3sm_v2_data_for_e3sm_diags/20210528.v2rc3e.piControl.ne30pg2_EC30to60E2r2.chrysalis/climatology/rgr/20210528.v2rc3e.piControl.ne30pg2_EC30to60E2r2.chrysalis_ANN_005101_006012_climo.nc.
RuntimeError: Neither does AODSO4_TRO nor the variables in [('AODSO4_TRO',)] exist in the file file:///global/cfs/cdirs/e3sm/e3sm_diags/postprocessed_e3sm_v2_data_for_e3sm_diags/20210528.v2rc3e.piControl.ne30pg2_EC30to60E2r2.chrysalis/climatology/rgr/20210528.v2rc3e.piControl.ne30pg2_EC30to60E2r2.chrysalis_JJA_005106_006008_climo.nc.
RuntimeError: Neither does in_cloud_cdnc nor the variables in [('cdnc', 'lcc')] exist in the file file:///global/cfs/cdirs/e3sm/e3sm_diags/postprocessed_e3sm_v2_data_for_e3sm_diags/20210528.v2rc3e.piControl.ne30pg2_EC30to60E2r2.chrysalis/climatology/rgr/20210528.v2rc3e.piControl.ne30pg2_EC30to60E2r2.chrysalis_01_005101_006001_climo.nc.
RuntimeError: Neither does in_cloud_cdnc nor the variables in [('cdnc', 'lcc')] exist in the file file:///global/cfs/cdirs/e3sm/e3sm_diags/postprocessed_e3sm_v2_data_for_e3sm_diags/20210528.v2rc3e.piControl.ne30pg2_EC30to60E2r2.chrysalis/climatology/rgr/20210528.v2rc3e.piControl.ne30pg2_EC30to60E2r2.chrysalis_ANN_005101_006012_climo.nc.
RuntimeError: Neither does in_cloud_cdnc nor the variables in [('cdnc', 'lcc')] exist in the file file:///global/cfs/cdirs/e3sm/e3sm_diags/postprocessed_e3sm_v2_data_for_e3sm_diags/20210528.v2rc3e.piControl.ne30pg2_EC30to60E2r2.chrysalis/climatology/rgr/20210528.v2rc3e.piControl.ne30pg2_EC30to60E2r2.chrysalis_JJA_005106_006008_climo.nc.
RuntimeError: Neither does in_cloud_lwp nor the variables in [('lwp', 'lcc')] exist in the file file:///global/cfs/cdirs/e3sm/e3sm_diags/postprocessed_e3sm_v2_data_for_e3sm_diags/20210528.v2rc3e.piControl.ne30pg2_EC30to60E2r2.chrysalis/climatology/rgr/20210528.v2rc3e.piControl.ne30pg2_EC30to60E2r2.chrysalis_01_005101_006001_climo.nc.
RuntimeError: Neither does in_cloud_lwp nor the variables in [('lwp', 'lcc')] exist in the file file:///global/cfs/cdirs/e3sm/e3sm_diags/postprocessed_e3sm_v2_data_for_e3sm_diags/20210528.v2rc3e.piControl.ne30pg2_EC30to60E2r2.chrysalis/climatology/rgr/20210528.v2rc3e.piControl.ne30pg2_EC30to60E2r2.chrysalis_ANN_005101_006012_climo.nc.
RuntimeError: Neither does in_cloud_lwp nor the variables in [('lwp', 'lcc')] exist in the file file:///global/cfs/cdirs/e3sm/e3sm_diags/postprocessed_e3sm_v2_data_for_e3sm_diags/20210528.v2rc3e.piControl.ne30pg2_EC30to60E2r2.chrysalis/climatology/rgr/20210528.v2rc3e.piControl.ne30pg2_EC30to60E2r2.chrysalis_JJA_005106_006008_climo.nc.
RuntimeError: Neither does in_grid_cdnc nor the variables in [('cdnc',)] exist in the file file:///global/cfs/cdirs/e3sm/e3sm_diags/postprocessed_e3sm_v2_data_for_e3sm_diags/20210528.v2rc3e.piControl.ne30pg2_EC30to60E2r2.chrysalis/climatology/rgr/20210528.v2rc3e.piControl.ne30pg2_EC30to60E2r2.chrysalis_01_005101_006001_climo.nc.
RuntimeError: Neither does in_grid_cdnc nor the variables in [('cdnc',)] exist in the file file:///global/cfs/cdirs/e3sm/e3sm_diags/postprocessed_e3sm_v2_data_for_e3sm_diags/20210528.v2rc3e.piControl.ne30pg2_EC30to60E2r2.chrysalis/climatology/rgr/20210528.v2rc3e.piControl.ne30pg2_EC30to60E2r2.chrysalis_ANN_005101_006012_climo.nc.
RuntimeError: Neither does in_grid_cdnc nor the variables in [('cdnc',)] exist in the file file:///global/cfs/cdirs/e3sm/e3sm_diags/postprocessed_e3sm_v2_data_for_e3sm_diags/20210528.v2rc3e.piControl.ne30pg2_EC30to60E2r2.chrysalis/climatology/rgr/20210528.v2rc3e.piControl.ne30pg2_EC30to60E2r2.chrysalis_JJA_005106_006008_climo.nc.
RuntimeError: Neither does in_grid_lwp nor the variables in [('lwp',)] exist in the file file:///global/cfs/cdirs/e3sm/e3sm_diags/postprocessed_e3sm_v2_data_for_e3sm_diags/20210528.v2rc3e.piControl.ne30pg2_EC30to60E2r2.chrysalis/climatology/rgr/20210528.v2rc3e.piControl.ne30pg2_EC30to60E2r2.chrysalis_01_005101_006001_climo.nc.
RuntimeError: Neither does in_grid_lwp nor the variables in [('lwp',)] exist in the file file:///global/cfs/cdirs/e3sm/e3sm_diags/postprocessed_e3sm_v2_data_for_e3sm_diags/20210528.v2rc3e.piControl.ne30pg2_EC30to60E2r2.chrysalis/climatology/rgr/20210528.v2rc3e.piControl.ne30pg2_EC30to60E2r2.chrysalis_ANN_005101_006012_climo.nc.
RuntimeError: Neither does in_grid_lwp nor the variables in [('lwp',)] exist in the file file:///global/cfs/cdirs/e3sm/e3sm_diags/postprocessed_e3sm_v2_data_for_e3sm_diags/20210528.v2rc3e.piControl.ne30pg2_EC30to60E2r2.chrysalis/climatology/rgr/20210528.v2rc3e.piControl.ne30pg2_EC30to60E2r2.chrysalis_JJA_005106_006008_climo.nc.
RuntimeError: Neither does _Mass_bc_200 nor the variables in [('Mass_bc_200',)] exist in the file file:///global/cfs/cdirs/e3sm/e3sm_diags/postprocessed_e3sm_v2_data_for_e3sm_diags/20210528.v2rc3e.piControl.ne30pg2_EC30to60E2r2.chrysalis/climatology/rgr/20210528.v2rc3e.piControl.ne30pg2_EC30to60E2r2.chrysalis_ANN_005101_006012_climo.nc.
RuntimeError: Neither does _Mass_bc_200 nor the variables in [('Mass_bc_200',)] exist in the file file:///global/cfs/cdirs/e3sm/e3sm_diags/postprocessed_e3sm_v2_data_for_e3sm_diags/20210528.v2rc3e.piControl.ne30pg2_EC30to60E2r2.chrysalis/climatology/rgr/20210528.v2rc3e.piControl.ne30pg2_EC30to60E2r2.chrysalis_JJA_005106_006008_climo.nc.
RuntimeError: Neither does _Mass_bc_330 nor the variables in [('Mass_bc_330',)] exist in the file file:///global/cfs/cdirs/e3sm/e3sm_diags/postprocessed_e3sm_v2_data_for_e3sm_diags/20210528.v2rc3e.piControl.ne30pg2_EC30to60E2r2.chrysalis/climatology/rgr/20210528.v2rc3e.piControl.ne30pg2_EC30to60E2r2.chrysalis_01_005101_006001_climo.nc.
RuntimeError: Neither does _Mass_bc_330 nor the variables in [('Mass_bc_330',)] exist in the file file:///global/cfs/cdirs/e3sm/e3sm_diags/postprocessed_e3sm_v2_data_for_e3sm_diags/20210528.v2rc3e.piControl.ne30pg2_EC30to60E2r2.chrysalis/climatology/rgr/20210528.v2rc3e.piControl.ne30pg2_EC30to60E2r2.chrysalis_ANN_005101_006012_climo.nc.
RuntimeError: Neither does _Mass_bc_330 nor the variables in [('Mass_bc_330',)] exist in the file file:///global/cfs/cdirs/e3sm/e3sm_diags/postprocessed_e3sm_v2_data_for_e3sm_diags/20210528.v2rc3e.piControl.ne30pg2_EC30to60E2r2.chrysalis/climatology/rgr/20210528.v2rc3e.piControl.ne30pg2_EC30to60E2r2.chrysalis_JJA_005106_006008_climo.nc.
RuntimeError: Neither does _Mass_bc_850 nor the variables in [('Mass_bc_850',)] exist in the file file:///global/cfs/cdirs/e3sm/e3sm_diags/postprocessed_e3sm_v2_data_for_e3sm_diags/20210528.v2rc3e.piControl.ne30pg2_EC30to60E2r2.chrysalis/climatology/rgr/20210528.v2rc3e.piControl.ne30pg2_EC30to60E2r2.chrysalis_01_005101_006001_climo.nc.
RuntimeError: Neither does _Mass_bc_850 nor the variables in [('Mass_bc_850',)] exist in the file file:///global/cfs/cdirs/e3sm/e3sm_diags/postprocessed_e3sm_v2_data_for_e3sm_diags/20210528.v2rc3e.piControl.ne30pg2_EC30to60E2r2.chrysalis/climatology/rgr/20210528.v2rc3e.piControl.ne30pg2_EC30to60E2r2.chrysalis_ANN_005101_006012_climo.nc.
RuntimeError: Neither does _Mass_bc_850 nor the variables in [('Mass_bc_850',)] exist in the file file:///global/cfs/cdirs/e3sm/e3sm_diags/postprocessed_e3sm_v2_data_for_e3sm_diags/20210528.v2rc3e.piControl.ne30pg2_EC30to60E2r2.chrysalis/climatology/rgr/20210528.v2rc3e.piControl.ne30pg2_EC30to60E2r2.chrysalis_JJA_005106_006008_climo.nc.
RuntimeError: Neither does _Mass_bc_srf nor the variables in [('Mass_bc_srf',)] exist in the file file:///global/cfs/cdirs/e3sm/e3sm_diags/postprocessed_e3sm_v2_data_for_e3sm_diags/20210528.v2rc3e.piControl.ne30pg2_EC30to60E2r2.chrysalis/climatology/rgr/20210528.v2rc3e.piControl.ne30pg2_EC30to60E2r2.chrysalis_01_005101_006001_climo.nc.
RuntimeError: Neither does _Mass_bc_srf nor the variables in [('Mass_bc_srf',)] exist in the file file:///global/cfs/cdirs/e3sm/e3sm_diags/postprocessed_e3sm_v2_data_for_e3sm_diags/20210528.v2rc3e.piControl.ne30pg2_EC30to60E2r2.chrysalis/climatology/rgr/20210528.v2rc3e.piControl.ne30pg2_EC30to60E2r2.chrysalis_ANN_005101_006012_climo.nc.
RuntimeError: Neither does _Mass_bc_srf nor the variables in [('Mass_bc_srf',)] exist in the file file:///global/cfs/cdirs/e3sm/e3sm_diags/postprocessed_e3sm_v2_data_for_e3sm_diags/20210528.v2rc3e.piControl.ne30pg2_EC30to60E2r2.chrysalis/climatology/rgr/20210528.v2rc3e.piControl.ne30pg2_EC30to60E2r2.chrysalis_JJA_005106_006008_climo.nc.
RuntimeError: Neither does _Mass_dst_200 nor the variables in [('Mass_dst_200',)] exist in the file file:///global/cfs/cdirs/e3sm/e3sm_diags/postprocessed_e3sm_v2_data_for_e3sm_diags/20210528.v2rc3e.piControl.ne30pg2_EC30to60E2r2.chrysalis/climatology/rgr/20210528.v2rc3e.piControl.ne30pg2_EC30to60E2r2.chrysalis_ANN_005101_006012_climo.nc.
RuntimeError: Neither does _Mass_dst_200 nor the variables in [('Mass_dst_200',)] exist in the file file:///global/cfs/cdirs/e3sm/e3sm_diags/postprocessed_e3sm_v2_data_for_e3sm_diags/20210528.v2rc3e.piControl.ne30pg2_EC30to60E2r2.chrysalis/climatology/rgr/20210528.v2rc3e.piControl.ne30pg2_EC30to60E2r2.chrysalis_JJA_005106_006008_climo.nc.
RuntimeError: Neither does _Mass_dst_330 nor the variables in [('Mass_dst_330',)] exist in the file file:///global/cfs/cdirs/e3sm/e3sm_diags/postprocessed_e3sm_v2_data_for_e3sm_diags/20210528.v2rc3e.piControl.ne30pg2_EC30to60E2r2.chrysalis/climatology/rgr/20210528.v2rc3e.piControl.ne30pg2_EC30to60E2r2.chrysalis_01_005101_006001_climo.nc.
RuntimeError: Neither does _Mass_dst_330 nor the variables in [('Mass_dst_330',)] exist in the file file:///global/cfs/cdirs/e3sm/e3sm_diags/postprocessed_e3sm_v2_data_for_e3sm_diags/20210528.v2rc3e.piControl.ne30pg2_EC30to60E2r2.chrysalis/climatology/rgr/20210528.v2rc3e.piControl.ne30pg2_EC30to60E2r2.chrysalis_ANN_005101_006012_climo.nc.
RuntimeError: Neither does _Mass_dst_330 nor the variables in [('Mass_dst_330',)] exist in the file file:///global/cfs/cdirs/e3sm/e3sm_diags/postprocessed_e3sm_v2_data_for_e3sm_diags/20210528.v2rc3e.piControl.ne30pg2_EC30to60E2r2.chrysalis/climatology/rgr/20210528.v2rc3e.piControl.ne30pg2_EC30to60E2r2.chrysalis_JJA_005106_006008_climo.nc.
RuntimeError: Neither does _Mass_dst_850 nor the variables in [('Mass_dst_850',)] exist in the file file:///global/cfs/cdirs/e3sm/e3sm_diags/postprocessed_e3sm_v2_data_for_e3sm_diags/20210528.v2rc3e.piControl.ne30pg2_EC30to60E2r2.chrysalis/climatology/rgr/20210528.v2rc3e.piControl.ne30pg2_EC30to60E2r2.chrysalis_01_005101_006001_climo.nc.
RuntimeError: Neither does _Mass_dst_850 nor the variables in [('Mass_dst_850',)] exist in the file file:///global/cfs/cdirs/e3sm/e3sm_diags/postprocessed_e3sm_v2_data_for_e3sm_diags/20210528.v2rc3e.piControl.ne30pg2_EC30to60E2r2.chrysalis/climatology/rgr/20210528.v2rc3e.piControl.ne30pg2_EC30to60E2r2.chrysalis_ANN_005101_006012_climo.nc.
RuntimeError: Neither does _Mass_dst_850 nor the variables in [('Mass_dst_850',)] exist in the file file:///global/cfs/cdirs/e3sm/e3sm_diags/postprocessed_e3sm_v2_data_for_e3sm_diags/20210528.v2rc3e.piControl.ne30pg2_EC30to60E2r2.chrysalis/climatology/rgr/20210528.v2rc3e.piControl.ne30pg2_EC30to60E2r2.chrysalis_JJA_005106_006008_climo.nc.
RuntimeError: Neither does _Mass_dst_srf nor the variables in [('Mass_dst_srf',)] exist in the file file:///global/cfs/cdirs/e3sm/e3sm_diags/postprocessed_e3sm_v2_data_for_e3sm_diags/20210528.v2rc3e.piControl.ne30pg2_EC30to60E2r2.chrysalis/climatology/rgr/20210528.v2rc3e.piControl.ne30pg2_EC30to60E2r2.chrysalis_01_005101_006001_climo.nc.
RuntimeError: Neither does _Mass_dst_srf nor the variables in [('Mass_dst_srf',)] exist in the file file:///global/cfs/cdirs/e3sm/e3sm_diags/postprocessed_e3sm_v2_data_for_e3sm_diags/20210528.v2rc3e.piControl.ne30pg2_EC30to60E2r2.chrysalis/climatology/rgr/20210528.v2rc3e.piControl.ne30pg2_EC30to60E2r2.chrysalis_ANN_005101_006012_climo.nc.
RuntimeError: Neither does _Mass_dst_srf nor the variables in [('Mass_dst_srf',)] exist in the file file:///global/cfs/cdirs/e3sm/e3sm_diags/postprocessed_e3sm_v2_data_for_e3sm_diags/20210528.v2rc3e.piControl.ne30pg2_EC30to60E2r2.chrysalis/climatology/rgr/20210528.v2rc3e.piControl.ne30pg2_EC30to60E2r2.chrysalis_JJA_005106_006008_climo.nc.
RuntimeError: Neither does _Mass_mom_200 nor the variables in [('Mass_mom_200',)] exist in the file file:///global/cfs/cdirs/e3sm/e3sm_diags/postprocessed_e3sm_v2_data_for_e3sm_diags/20210528.v2rc3e.piControl.ne30pg2_EC30to60E2r2.chrysalis/climatology/rgr/20210528.v2rc3e.piControl.ne30pg2_EC30to60E2r2.chrysalis_ANN_005101_006012_climo.nc.
RuntimeError: Neither does _Mass_mom_200 nor the variables in [('Mass_mom_200',)] exist in the file file:///global/cfs/cdirs/e3sm/e3sm_diags/postprocessed_e3sm_v2_data_for_e3sm_diags/20210528.v2rc3e.piControl.ne30pg2_EC30to60E2r2.chrysalis/climatology/rgr/20210528.v2rc3e.piControl.ne30pg2_EC30to60E2r2.chrysalis_JJA_005106_006008_climo.nc.
RuntimeError: Neither does _Mass_mom_330 nor the variables in [('Mass_mom_330',)] exist in the file file:///global/cfs/cdirs/e3sm/e3sm_diags/postprocessed_e3sm_v2_data_for_e3sm_diags/20210528.v2rc3e.piControl.ne30pg2_EC30to60E2r2.chrysalis/climatology/rgr/20210528.v2rc3e.piControl.ne30pg2_EC30to60E2r2.chrysalis_01_005101_006001_climo.nc.
RuntimeError: Neither does _Mass_mom_330 nor the variables in [('Mass_mom_330',)] exist in the file file:///global/cfs/cdirs/e3sm/e3sm_diags/postprocessed_e3sm_v2_data_for_e3sm_diags/20210528.v2rc3e.piControl.ne30pg2_EC30to60E2r2.chrysalis/climatology/rgr/20210528.v2rc3e.piControl.ne30pg2_EC30to60E2r2.chrysalis_ANN_005101_006012_climo.nc.
RuntimeError: Neither does _Mass_mom_330 nor the variables in [('Mass_mom_330',)] exist in the file file:///global/cfs/cdirs/e3sm/e3sm_diags/postprocessed_e3sm_v2_data_for_e3sm_diags/20210528.v2rc3e.piControl.ne30pg2_EC30to60E2r2.chrysalis/climatology/rgr/20210528.v2rc3e.piControl.ne30pg2_EC30to60E2r2.chrysalis_JJA_005106_006008_climo.nc.
RuntimeError: Neither does _Mass_mom_850 nor the variables in [('Mass_mom_850',)] exist in the file file:///global/cfs/cdirs/e3sm/e3sm_diags/postprocessed_e3sm_v2_data_for_e3sm_diags/20210528.v2rc3e.piControl.ne30pg2_EC30to60E2r2.chrysalis/climatology/rgr/20210528.v2rc3e.piControl.ne30pg2_EC30to60E2r2.chrysalis_01_005101_006001_climo.nc.
RuntimeError: Neither does _Mass_mom_850 nor the variables in [('Mass_mom_850',)] exist in the file file:///global/cfs/cdirs/e3sm/e3sm_diags/postprocessed_e3sm_v2_data_for_e3sm_diags/20210528.v2rc3e.piControl.ne30pg2_EC30to60E2r2.chrysalis/climatology/rgr/20210528.v2rc3e.piControl.ne30pg2_EC30to60E2r2.chrysalis_ANN_005101_006012_climo.nc.
RuntimeError: Neither does _Mass_mom_850 nor the variables in [('Mass_mom_850',)] exist in the file file:///global/cfs/cdirs/e3sm/e3sm_diags/postprocessed_e3sm_v2_data_for_e3sm_diags/20210528.v2rc3e.piControl.ne30pg2_EC30to60E2r2.chrysalis/climatology/rgr/20210528.v2rc3e.piControl.ne30pg2_EC30to60E2r2.chrysalis_JJA_005106_006008_climo.nc.
RuntimeError: Neither does _Mass_mom_srf nor the variables in [('Mass_mom_srf',)] exist in the file file:///global/cfs/cdirs/e3sm/e3sm_diags/postprocessed_e3sm_v2_data_for_e3sm_diags/20210528.v2rc3e.piControl.ne30pg2_EC30to60E2r2.chrysalis/climatology/rgr/20210528.v2rc3e.piControl.ne30pg2_EC30to60E2r2.chrysalis_01_005101_006001_climo.nc.
RuntimeError: Neither does _Mass_mom_srf nor the variables in [('Mass_mom_srf',)] exist in the file file:///global/cfs/cdirs/e3sm/e3sm_diags/postprocessed_e3sm_v2_data_for_e3sm_diags/20210528.v2rc3e.piControl.ne30pg2_EC30to60E2r2.chrysalis/climatology/rgr/20210528.v2rc3e.piControl.ne30pg2_EC30to60E2r2.chrysalis_ANN_005101_006012_climo.nc.
RuntimeError: Neither does _Mass_mom_srf nor the variables in [('Mass_mom_srf',)] exist in the file file:///global/cfs/cdirs/e3sm/e3sm_diags/postprocessed_e3sm_v2_data_for_e3sm_diags/20210528.v2rc3e.piControl.ne30pg2_EC30to60E2r2.chrysalis/climatology/rgr/20210528.v2rc3e.piControl.ne30pg2_EC30to60E2r2.chrysalis_JJA_005106_006008_climo.nc.
RuntimeError: Neither does _Mass_ncl_200 nor the variables in [('Mass_ncl_200',)] exist in the file file:///global/cfs/cdirs/e3sm/e3sm_diags/postprocessed_e3sm_v2_data_for_e3sm_diags/20210528.v2rc3e.piControl.ne30pg2_EC30to60E2r2.chrysalis/climatology/rgr/20210528.v2rc3e.piControl.ne30pg2_EC30to60E2r2.chrysalis_ANN_005101_006012_climo.nc.
RuntimeError: Neither does _Mass_ncl_200 nor the variables in [('Mass_ncl_200',)] exist in the file file:///global/cfs/cdirs/e3sm/e3sm_diags/postprocessed_e3sm_v2_data_for_e3sm_diags/20210528.v2rc3e.piControl.ne30pg2_EC30to60E2r2.chrysalis/climatology/rgr/20210528.v2rc3e.piControl.ne30pg2_EC30to60E2r2.chrysalis_JJA_005106_006008_climo.nc.
RuntimeError: Neither does _Mass_ncl_330 nor the variables in [('Mass_ncl_330',)] exist in the file file:///global/cfs/cdirs/e3sm/e3sm_diags/postprocessed_e3sm_v2_data_for_e3sm_diags/20210528.v2rc3e.piControl.ne30pg2_EC30to60E2r2.chrysalis/climatology/rgr/20210528.v2rc3e.piControl.ne30pg2_EC30to60E2r2.chrysalis_01_005101_006001_climo.nc.
RuntimeError: Neither does _Mass_ncl_330 nor the variables in [('Mass_ncl_330',)] exist in the file file:///global/cfs/cdirs/e3sm/e3sm_diags/postprocessed_e3sm_v2_data_for_e3sm_diags/20210528.v2rc3e.piControl.ne30pg2_EC30to60E2r2.chrysalis/climatology/rgr/20210528.v2rc3e.piControl.ne30pg2_EC30to60E2r2.chrysalis_ANN_005101_006012_climo.nc.
RuntimeError: Neither does _Mass_ncl_330 nor the variables in [('Mass_ncl_330',)] exist in the file file:///global/cfs/cdirs/e3sm/e3sm_diags/postprocessed_e3sm_v2_data_for_e3sm_diags/20210528.v2rc3e.piControl.ne30pg2_EC30to60E2r2.chrysalis/climatology/rgr/20210528.v2rc3e.piControl.ne30pg2_EC30to60E2r2.chrysalis_JJA_005106_006008_climo.nc.
RuntimeError: Neither does _Mass_ncl_850 nor the variables in [('Mass_ncl_850',)] exist in the file file:///global/cfs/cdirs/e3sm/e3sm_diags/postprocessed_e3sm_v2_data_for_e3sm_diags/20210528.v2rc3e.piControl.ne30pg2_EC30to60E2r2.chrysalis/climatology/rgr/20210528.v2rc3e.piControl.ne30pg2_EC30to60E2r2.chrysalis_01_005101_006001_climo.nc.
RuntimeError: Neither does _Mass_ncl_850 nor the variables in [('Mass_ncl_850',)] exist in the file file:///global/cfs/cdirs/e3sm/e3sm_diags/postprocessed_e3sm_v2_data_for_e3sm_diags/20210528.v2rc3e.piControl.ne30pg2_EC30to60E2r2.chrysalis/climatology/rgr/20210528.v2rc3e.piControl.ne30pg2_EC30to60E2r2.chrysalis_ANN_005101_006012_climo.nc.
RuntimeError: Neither does _Mass_ncl_850 nor the variables in [('Mass_ncl_850',)] exist in the file file:///global/cfs/cdirs/e3sm/e3sm_diags/postprocessed_e3sm_v2_data_for_e3sm_diags/20210528.v2rc3e.piControl.ne30pg2_EC30to60E2r2.chrysalis/climatology/rgr/20210528.v2rc3e.piControl.ne30pg2_EC30to60E2r2.chrysalis_JJA_005106_006008_climo.nc.
RuntimeError: Neither does _Mass_ncl_srf nor the variables in [('Mass_ncl_srf',)] exist in the file file:///global/cfs/cdirs/e3sm/e3sm_diags/postprocessed_e3sm_v2_data_for_e3sm_diags/20210528.v2rc3e.piControl.ne30pg2_EC30to60E2r2.chrysalis/climatology/rgr/20210528.v2rc3e.piControl.ne30pg2_EC30to60E2r2.chrysalis_01_005101_006001_climo.nc.
RuntimeError: Neither does _Mass_ncl_srf nor the variables in [('Mass_ncl_srf',)] exist in the file file:///global/cfs/cdirs/e3sm/e3sm_diags/postprocessed_e3sm_v2_data_for_e3sm_diags/20210528.v2rc3e.piControl.ne30pg2_EC30to60E2r2.chrysalis/climatology/rgr/20210528.v2rc3e.piControl.ne30pg2_EC30to60E2r2.chrysalis_ANN_005101_006012_climo.nc.
RuntimeError: Neither does _Mass_ncl_srf nor the variables in [('Mass_ncl_srf',)] exist in the file file:///global/cfs/cdirs/e3sm/e3sm_diags/postprocessed_e3sm_v2_data_for_e3sm_diags/20210528.v2rc3e.piControl.ne30pg2_EC30to60E2r2.chrysalis/climatology/rgr/20210528.v2rc3e.piControl.ne30pg2_EC30to60E2r2.chrysalis_JJA_005106_006008_climo.nc.
RuntimeError: Neither does _Mass_pom_200 nor the variables in [('Mass_pom_200',)] exist in the file file:///global/cfs/cdirs/e3sm/e3sm_diags/postprocessed_e3sm_v2_data_for_e3sm_diags/20210528.v2rc3e.piControl.ne30pg2_EC30to60E2r2.chrysalis/climatology/rgr/20210528.v2rc3e.piControl.ne30pg2_EC30to60E2r2.chrysalis_ANN_005101_006012_climo.nc.
RuntimeError: Neither does _Mass_pom_200 nor the variables in [('Mass_pom_200',)] exist in the file file:///global/cfs/cdirs/e3sm/e3sm_diags/postprocessed_e3sm_v2_data_for_e3sm_diags/20210528.v2rc3e.piControl.ne30pg2_EC30to60E2r2.chrysalis/climatology/rgr/20210528.v2rc3e.piControl.ne30pg2_EC30to60E2r2.chrysalis_JJA_005106_006008_climo.nc.
RuntimeError: Neither does _Mass_pom_330 nor the variables in [('Mass_pom_330',)] exist in the file file:///global/cfs/cdirs/e3sm/e3sm_diags/postprocessed_e3sm_v2_data_for_e3sm_diags/20210528.v2rc3e.piControl.ne30pg2_EC30to60E2r2.chrysalis/climatology/rgr/20210528.v2rc3e.piControl.ne30pg2_EC30to60E2r2.chrysalis_01_005101_006001_climo.nc.
RuntimeError: Neither does _Mass_pom_330 nor the variables in [('Mass_pom_330',)] exist in the file file:///global/cfs/cdirs/e3sm/e3sm_diags/postprocessed_e3sm_v2_data_for_e3sm_diags/20210528.v2rc3e.piControl.ne30pg2_EC30to60E2r2.chrysalis/climatology/rgr/20210528.v2rc3e.piControl.ne30pg2_EC30to60E2r2.chrysalis_ANN_005101_006012_climo.nc.
RuntimeError: Neither does _Mass_pom_330 nor the variables in [('Mass_pom_330',)] exist in the file file:///global/cfs/cdirs/e3sm/e3sm_diags/postprocessed_e3sm_v2_data_for_e3sm_diags/20210528.v2rc3e.piControl.ne30pg2_EC30to60E2r2.chrysalis/climatology/rgr/20210528.v2rc3e.piControl.ne30pg2_EC30to60E2r2.chrysalis_JJA_005106_006008_climo.nc.
RuntimeError: Neither does _Mass_pom_850 nor the variables in [('Mass_pom_850',)] exist in the file file:///global/cfs/cdirs/e3sm/e3sm_diags/postprocessed_e3sm_v2_data_for_e3sm_diags/20210528.v2rc3e.piControl.ne30pg2_EC30to60E2r2.chrysalis/climatology/rgr/20210528.v2rc3e.piControl.ne30pg2_EC30to60E2r2.chrysalis_01_005101_006001_climo.nc.
RuntimeError: Neither does _Mass_pom_850 nor the variables in [('Mass_pom_850',)] exist in the file file:///global/cfs/cdirs/e3sm/e3sm_diags/postprocessed_e3sm_v2_data_for_e3sm_diags/20210528.v2rc3e.piControl.ne30pg2_EC30to60E2r2.chrysalis/climatology/rgr/20210528.v2rc3e.piControl.ne30pg2_EC30to60E2r2.chrysalis_ANN_005101_006012_climo.nc.
RuntimeError: Neither does _Mass_pom_850 nor the variables in [('Mass_pom_850',)] exist in the file file:///global/cfs/cdirs/e3sm/e3sm_diags/postprocessed_e3sm_v2_data_for_e3sm_diags/20210528.v2rc3e.piControl.ne30pg2_EC30to60E2r2.chrysalis/climatology/rgr/20210528.v2rc3e.piControl.ne30pg2_EC30to60E2r2.chrysalis_JJA_005106_006008_climo.nc.
RuntimeError: Neither does _Mass_pom_srf nor the variables in [('Mass_pom_srf',)] exist in the file file:///global/cfs/cdirs/e3sm/e3sm_diags/postprocessed_e3sm_v2_data_for_e3sm_diags/20210528.v2rc3e.piControl.ne30pg2_EC30to60E2r2.chrysalis/climatology/rgr/20210528.v2rc3e.piControl.ne30pg2_EC30to60E2r2.chrysalis_01_005101_006001_climo.nc.
RuntimeError: Neither does _Mass_pom_srf nor the variables in [('Mass_pom_srf',)] exist in the file file:///global/cfs/cdirs/e3sm/e3sm_diags/postprocessed_e3sm_v2_data_for_e3sm_diags/20210528.v2rc3e.piControl.ne30pg2_EC30to60E2r2.chrysalis/climatology/rgr/20210528.v2rc3e.piControl.ne30pg2_EC30to60E2r2.chrysalis_ANN_005101_006012_climo.nc.
RuntimeError: Neither does _Mass_pom_srf nor the variables in [('Mass_pom_srf',)] exist in the file file:///global/cfs/cdirs/e3sm/e3sm_diags/postprocessed_e3sm_v2_data_for_e3sm_diags/20210528.v2rc3e.piControl.ne30pg2_EC30to60E2r2.chrysalis/climatology/rgr/20210528.v2rc3e.piControl.ne30pg2_EC30to60E2r2.chrysalis_JJA_005106_006008_climo.nc.
RuntimeError: Neither does _Mass_so4_200 nor the variables in [('Mass_so4_200',)] exist in the file file:///global/cfs/cdirs/e3sm/e3sm_diags/postprocessed_e3sm_v2_data_for_e3sm_diags/20210528.v2rc3e.piControl.ne30pg2_EC30to60E2r2.chrysalis/climatology/rgr/20210528.v2rc3e.piControl.ne30pg2_EC30to60E2r2.chrysalis_ANN_005101_006012_climo.nc.
RuntimeError: Neither does _Mass_so4_200 nor the variables in [('Mass_so4_200',)] exist in the file file:///global/cfs/cdirs/e3sm/e3sm_diags/postprocessed_e3sm_v2_data_for_e3sm_diags/20210528.v2rc3e.piControl.ne30pg2_EC30to60E2r2.chrysalis/climatology/rgr/20210528.v2rc3e.piControl.ne30pg2_EC30to60E2r2.chrysalis_JJA_005106_006008_climo.nc.
RuntimeError: Neither does _Mass_so4_330 nor the variables in [('Mass_so4_330',)] exist in the file file:///global/cfs/cdirs/e3sm/e3sm_diags/postprocessed_e3sm_v2_data_for_e3sm_diags/20210528.v2rc3e.piControl.ne30pg2_EC30to60E2r2.chrysalis/climatology/rgr/20210528.v2rc3e.piControl.ne30pg2_EC30to60E2r2.chrysalis_01_005101_006001_climo.nc.
RuntimeError: Neither does _Mass_so4_330 nor the variables in [('Mass_so4_330',)] exist in the file file:///global/cfs/cdirs/e3sm/e3sm_diags/postprocessed_e3sm_v2_data_for_e3sm_diags/20210528.v2rc3e.piControl.ne30pg2_EC30to60E2r2.chrysalis/climatology/rgr/20210528.v2rc3e.piControl.ne30pg2_EC30to60E2r2.chrysalis_ANN_005101_006012_climo.nc.
RuntimeError: Neither does _Mass_so4_330 nor the variables in [('Mass_so4_330',)] exist in the file file:///global/cfs/cdirs/e3sm/e3sm_diags/postprocessed_e3sm_v2_data_for_e3sm_diags/20210528.v2rc3e.piControl.ne30pg2_EC30to60E2r2.chrysalis/climatology/rgr/20210528.v2rc3e.piControl.ne30pg2_EC30to60E2r2.chrysalis_JJA_005106_006008_climo.nc.
RuntimeError: Neither does _Mass_so4_850 nor the variables in [('Mass_so4_850',)] exist in the file file:///global/cfs/cdirs/e3sm/e3sm_diags/postprocessed_e3sm_v2_data_for_e3sm_diags/20210528.v2rc3e.piControl.ne30pg2_EC30to60E2r2.chrysalis/climatology/rgr/20210528.v2rc3e.piControl.ne30pg2_EC30to60E2r2.chrysalis_01_005101_006001_climo.nc.
RuntimeError: Neither does _Mass_so4_850 nor the variables in [('Mass_so4_850',)] exist in the file file:///global/cfs/cdirs/e3sm/e3sm_diags/postprocessed_e3sm_v2_data_for_e3sm_diags/20210528.v2rc3e.piControl.ne30pg2_EC30to60E2r2.chrysalis/climatology/rgr/20210528.v2rc3e.piControl.ne30pg2_EC30to60E2r2.chrysalis_ANN_005101_006012_climo.nc.
RuntimeError: Neither does _Mass_so4_850 nor the variables in [('Mass_so4_850',)] exist in the file file:///global/cfs/cdirs/e3sm/e3sm_diags/postprocessed_e3sm_v2_data_for_e3sm_diags/20210528.v2rc3e.piControl.ne30pg2_EC30to60E2r2.chrysalis/climatology/rgr/20210528.v2rc3e.piControl.ne30pg2_EC30to60E2r2.chrysalis_JJA_005106_006008_climo.nc.
RuntimeError: Neither does _Mass_so4_srf nor the variables in [('Mass_so4_srf',)] exist in the file file:///global/cfs/cdirs/e3sm/e3sm_diags/postprocessed_e3sm_v2_data_for_e3sm_diags/20210528.v2rc3e.piControl.ne30pg2_EC30to60E2r2.chrysalis/climatology/rgr/20210528.v2rc3e.piControl.ne30pg2_EC30to60E2r2.chrysalis_01_005101_006001_climo.nc.
RuntimeError: Neither does _Mass_so4_srf nor the variables in [('Mass_so4_srf',)] exist in the file file:///global/cfs/cdirs/e3sm/e3sm_diags/postprocessed_e3sm_v2_data_for_e3sm_diags/20210528.v2rc3e.piControl.ne30pg2_EC30to60E2r2.chrysalis/climatology/rgr/20210528.v2rc3e.piControl.ne30pg2_EC30to60E2r2.chrysalis_ANN_005101_006012_climo.nc.
RuntimeError: Neither does _Mass_so4_srf nor the variables in [('Mass_so4_srf',)] exist in the file file:///global/cfs/cdirs/e3sm/e3sm_diags/postprocessed_e3sm_v2_data_for_e3sm_diags/20210528.v2rc3e.piControl.ne30pg2_EC30to60E2r2.chrysalis/climatology/rgr/20210528.v2rc3e.piControl.ne30pg2_EC30to60E2r2.chrysalis_JJA_005106_006008_climo.nc.
RuntimeError: Neither does _Mass_soa_200 nor the variables in [('Mass_soa_200',)] exist in the file file:///global/cfs/cdirs/e3sm/e3sm_diags/postprocessed_e3sm_v2_data_for_e3sm_diags/20210528.v2rc3e.piControl.ne30pg2_EC30to60E2r2.chrysalis/climatology/rgr/20210528.v2rc3e.piControl.ne30pg2_EC30to60E2r2.chrysalis_ANN_005101_006012_climo.nc.
RuntimeError: Neither does _Mass_soa_200 nor the variables in [('Mass_soa_200',)] exist in the file file:///global/cfs/cdirs/e3sm/e3sm_diags/postprocessed_e3sm_v2_data_for_e3sm_diags/20210528.v2rc3e.piControl.ne30pg2_EC30to60E2r2.chrysalis/climatology/rgr/20210528.v2rc3e.piControl.ne30pg2_EC30to60E2r2.chrysalis_JJA_005106_006008_climo.nc.
RuntimeError: Neither does _Mass_soa_330 nor the variables in [('Mass_soa_330',)] exist in the file file:///global/cfs/cdirs/e3sm/e3sm_diags/postprocessed_e3sm_v2_data_for_e3sm_diags/20210528.v2rc3e.piControl.ne30pg2_EC30to60E2r2.chrysalis/climatology/rgr/20210528.v2rc3e.piControl.ne30pg2_EC30to60E2r2.chrysalis_01_005101_006001_climo.nc.
RuntimeError: Neither does _Mass_soa_330 nor the variables in [('Mass_soa_330',)] exist in the file file:///global/cfs/cdirs/e3sm/e3sm_diags/postprocessed_e3sm_v2_data_for_e3sm_diags/20210528.v2rc3e.piControl.ne30pg2_EC30to60E2r2.chrysalis/climatology/rgr/20210528.v2rc3e.piControl.ne30pg2_EC30to60E2r2.chrysalis_ANN_005101_006012_climo.nc.
RuntimeError: Neither does _Mass_soa_330 nor the variables in [('Mass_soa_330',)] exist in the file file:///global/cfs/cdirs/e3sm/e3sm_diags/postprocessed_e3sm_v2_data_for_e3sm_diags/20210528.v2rc3e.piControl.ne30pg2_EC30to60E2r2.chrysalis/climatology/rgr/20210528.v2rc3e.piControl.ne30pg2_EC30to60E2r2.chrysalis_JJA_005106_006008_climo.nc.
RuntimeError: Neither does _Mass_soa_850 nor the variables in [('Mass_soa_850',)] exist in the file file:///global/cfs/cdirs/e3sm/e3sm_diags/postprocessed_e3sm_v2_data_for_e3sm_diags/20210528.v2rc3e.piControl.ne30pg2_EC30to60E2r2.chrysalis/climatology/rgr/20210528.v2rc3e.piControl.ne30pg2_EC30to60E2r2.chrysalis_01_005101_006001_climo.nc.
RuntimeError: Neither does _Mass_soa_850 nor the variables in [('Mass_soa_850',)] exist in the file file:///global/cfs/cdirs/e3sm/e3sm_diags/postprocessed_e3sm_v2_data_for_e3sm_diags/20210528.v2rc3e.piControl.ne30pg2_EC30to60E2r2.chrysalis/climatology/rgr/20210528.v2rc3e.piControl.ne30pg2_EC30to60E2r2.chrysalis_ANN_005101_006012_climo.nc.
RuntimeError: Neither does _Mass_soa_850 nor the variables in [('Mass_soa_850',)] exist in the file file:///global/cfs/cdirs/e3sm/e3sm_diags/postprocessed_e3sm_v2_data_for_e3sm_diags/20210528.v2rc3e.piControl.ne30pg2_EC30to60E2r2.chrysalis/climatology/rgr/20210528.v2rc3e.piControl.ne30pg2_EC30to60E2r2.chrysalis_JJA_005106_006008_climo.nc.
RuntimeError: Neither does _Mass_soa_srf nor the variables in [('Mass_soa_srf',)] exist in the file file:///global/cfs/cdirs/e3sm/e3sm_diags/postprocessed_e3sm_v2_data_for_e3sm_diags/20210528.v2rc3e.piControl.ne30pg2_EC30to60E2r2.chrysalis/climatology/rgr/20210528.v2rc3e.piControl.ne30pg2_EC30to60E2r2.chrysalis_01_005101_006001_climo.nc.
RuntimeError: Neither does _Mass_soa_srf nor the variables in [('Mass_soa_srf',)] exist in the file file:///global/cfs/cdirs/e3sm/e3sm_diags/postprocessed_e3sm_v2_data_for_e3sm_diags/20210528.v2rc3e.piControl.ne30pg2_EC30to60E2r2.chrysalis/climatology/rgr/20210528.v2rc3e.piControl.ne30pg2_EC30to60E2r2.chrysalis_ANN_005101_006012_climo.nc.
RuntimeError: Neither does _Mass_soa_srf nor the variables in [('Mass_soa_srf',)] exist in the file file:///global/cfs/cdirs/e3sm/e3sm_diags/postprocessed_e3sm_v2_data_for_e3sm_diags/20210528.v2rc3e.piControl.ne30pg2_EC30to60E2r2.chrysalis/climatology/rgr/20210528.v2rc3e.piControl.ne30pg2_EC30to60E2r2.chrysalis_JJA_005106_006008_climo.nc.
RuntimeError: Neither does QFLX nor the variables in [('evspsbl',), ('QFLX',), ('surf_evap',)] have valid files in /global/cfs/cdirs/e3sm/diagnostics/observations/Atm/time-series/.
RuntimeError: Neither does RESTOM nor the variables in [('RESTOA',), ('toa_net_all_mon',), ('FSNT', 'FLNT'), ('SW_flux_dn_at_model_top', 'SW_flux_up_at_model_top', 'LW_flux_up_at_model_top'), ('rtmt',)] have valid files in /global/cfs/cdirs/e3sm/e3sm_diags/postprocessed_e3sm_v2_data_for_e3sm_diags/20210528.v2rc3e.piControl.ne30pg2_EC30to60E2r2.chrysalis/time-series/rgr/.
